[2024-04-12T12:47:53.933+0000] {taskinstance.py:1979} INFO - Dependencies all met for dep_context=non-requeueable deps ti=<TaskInstance: KingFX_ETL.Extract_Response manual__2024-04-12T12:47:52.019626+00:00 [queued]>
[2024-04-12T12:47:53.942+0000] {taskinstance.py:1979} INFO - Dependencies all met for dep_context=requeueable deps ti=<TaskInstance: KingFX_ETL.Extract_Response manual__2024-04-12T12:47:52.019626+00:00 [queued]>
[2024-04-12T12:47:53.943+0000] {taskinstance.py:2193} INFO - Starting attempt 1 of 0
[2024-04-12T12:47:53.958+0000] {taskinstance.py:2217} INFO - Executing <Task(PythonOperator): Extract_Response> on 2024-04-12 12:47:52.019626+00:00
[2024-04-12T12:47:53.975+0000] {standard_task_runner.py:60} INFO - Started process 8353 to run task
[2024-04-12T12:47:53.982+0000] {standard_task_runner.py:87} INFO - Running: ['***', 'tasks', 'run', 'KingFX_ETL', 'Extract_Response', 'manual__2024-04-12T12:47:52.019626+00:00', '--job-id', '19', '--raw', '--subdir', 'DAGS_FOLDER/include/fx_dag.py', '--cfg-path', '/tmp/tmpfgd2or56']
[2024-04-12T12:47:53.986+0000] {standard_task_runner.py:88} INFO - Job 19: Subtask Extract_Response
[2024-04-12T12:47:54.061+0000] {task_command.py:423} INFO - Running <TaskInstance: KingFX_ETL.Extract_Response manual__2024-04-12T12:47:52.019626+00:00 [running]> on host ab7b3f965e72
[2024-04-12T12:47:54.142+0000] {taskinstance.py:2513} INFO - Exporting env vars: AIRFLOW_CTX_DAG_OWNER='kresthill' AIRFLOW_CTX_DAG_ID='KingFX_ETL' AIRFLOW_CTX_TASK_ID='Extract_Response' AIRFLOW_CTX_EXECUTION_DATE='2024-04-12T12:47:52.019626+00:00' AIRFLOW_CTX_TRY_NUMBER='1' AIRFLOW_CTX_DAG_RUN_ID='manual__2024-04-12T12:47:52.019626+00:00'
[2024-04-12T12:47:54.156+0000] {taskinstance.py:2731} ERROR - Task failed with exception
Traceback (most recent call last):
  File "/home/airflow/.local/lib/python3.8/site-packages/urllib3/connection.py", line 198, in _new_conn
    sock = connection.create_connection(
  File "/home/airflow/.local/lib/python3.8/site-packages/urllib3/util/connection.py", line 60, in create_connection
    for res in socket.getaddrinfo(host, port, family, socket.SOCK_STREAM):
  File "/usr/local/lib/python3.8/socket.py", line 918, in getaddrinfo
    for res in _socket.getaddrinfo(host, port, family, type, proto, flags):
socket.gaierror: [Errno -2] Name or service not known

The above exception was the direct cause of the following exception:

Traceback (most recent call last):
  File "/home/airflow/.local/lib/python3.8/site-packages/urllib3/connectionpool.py", line 793, in urlopen
    response = self._make_request(
  File "/home/airflow/.local/lib/python3.8/site-packages/urllib3/connectionpool.py", line 491, in _make_request
    raise new_e
  File "/home/airflow/.local/lib/python3.8/site-packages/urllib3/connectionpool.py", line 467, in _make_request
    self._validate_conn(conn)
  File "/home/airflow/.local/lib/python3.8/site-packages/urllib3/connectionpool.py", line 1099, in _validate_conn
    conn.connect()
  File "/home/airflow/.local/lib/python3.8/site-packages/urllib3/connection.py", line 616, in connect
    self.sock = sock = self._new_conn()
  File "/home/airflow/.local/lib/python3.8/site-packages/urllib3/connection.py", line 205, in _new_conn
    raise NameResolutionError(self.host, self, e) from e
urllib3.exceptions.NameResolutionError: <urllib3.connection.HTTPSConnection object at 0x7f3147e8eac0>: Failed to resolve 'xecdapi.xe.com' ([Errno -2] Name or service not known)

The above exception was the direct cause of the following exception:

Traceback (most recent call last):
  File "/home/airflow/.local/lib/python3.8/site-packages/requests/adapters.py", line 486, in send
    resp = conn.urlopen(
  File "/home/airflow/.local/lib/python3.8/site-packages/urllib3/connectionpool.py", line 847, in urlopen
    retries = retries.increment(
  File "/home/airflow/.local/lib/python3.8/site-packages/urllib3/util/retry.py", line 515, in increment
    raise MaxRetryError(_pool, url, reason) from reason  # type: ignore[arg-type]
urllib3.exceptions.MaxRetryError: HTTPSConnectionPool(host='xecdapi.xe.com', port=443): Max retries exceeded with url: /v1/convert_from.json/?from=USD&to=NGN,GHS,KES,UGX,MAD,XOF,EGP (Caused by NameResolutionError("<urllib3.connection.HTTPSConnection object at 0x7f3147e8eac0>: Failed to resolve 'xecdapi.xe.com' ([Errno -2] Name or service not known)"))

During handling of the above exception, another exception occurred:

Traceback (most recent call last):
  File "/home/airflow/.local/lib/python3.8/site-packages/airflow/models/taskinstance.py", line 444, in _execute_task
    result = _execute_callable(context=context, **execute_callable_kwargs)
  File "/home/airflow/.local/lib/python3.8/site-packages/airflow/models/taskinstance.py", line 414, in _execute_callable
    return execute_callable(context=context, **execute_callable_kwargs)
  File "/home/airflow/.local/lib/python3.8/site-packages/airflow/operators/python.py", line 200, in execute
    return_value = self.execute_callable()
  File "/home/airflow/.local/lib/python3.8/site-packages/airflow/operators/python.py", line 217, in execute_callable
    return self.python_callable(*self.op_args, **self.op_kwargs)
  File "/opt/airflow/dags/include/extract.py", line 22, in extract_data
    response = requests.get(url, auth=(api_id, api_key)).json()
  File "/home/airflow/.local/lib/python3.8/site-packages/requests/api.py", line 73, in get
    return request("get", url, params=params, **kwargs)
  File "/home/airflow/.local/lib/python3.8/site-packages/requests/api.py", line 59, in request
    return session.request(method=method, url=url, **kwargs)
  File "/home/airflow/.local/lib/python3.8/site-packages/requests/sessions.py", line 589, in request
    resp = self.send(prep, **send_kwargs)
  File "/home/airflow/.local/lib/python3.8/site-packages/requests/sessions.py", line 703, in send
    r = adapter.send(request, **kwargs)
  File "/home/airflow/.local/lib/python3.8/site-packages/requests/adapters.py", line 519, in send
    raise ConnectionError(e, request=request)
requests.exceptions.ConnectionError: HTTPSConnectionPool(host='xecdapi.xe.com', port=443): Max retries exceeded with url: /v1/convert_from.json/?from=USD&to=NGN,GHS,KES,UGX,MAD,XOF,EGP (Caused by NameResolutionError("<urllib3.connection.HTTPSConnection object at 0x7f3147e8eac0>: Failed to resolve 'xecdapi.xe.com' ([Errno -2] Name or service not known)"))
[2024-04-12T12:47:54.173+0000] {taskinstance.py:1149} INFO - Marking task as FAILED. dag_id=KingFX_ETL, task_id=Extract_Response, execution_date=20240412T124752, start_date=20240412T124753, end_date=20240412T124754
[2024-04-12T12:47:54.185+0000] {standard_task_runner.py:107} ERROR - Failed to execute job 19 for task Extract_Response (HTTPSConnectionPool(host='xecdapi.xe.com', port=443): Max retries exceeded with url: /v1/convert_from.json/?from=USD&to=NGN,GHS,KES,UGX,MAD,XOF,EGP (Caused by NameResolutionError("<urllib3.connection.HTTPSConnection object at 0x7f3147e8eac0>: Failed to resolve 'xecdapi.xe.com' ([Errno -2] Name or service not known)")); 8353)
[2024-04-12T12:47:54.194+0000] {local_task_job_runner.py:234} INFO - Task exited with return code 1
