[2024-04-13T00:20:32.402+0000] {taskinstance.py:1979} INFO - Dependencies all met for dep_context=non-requeueable deps ti=<TaskInstance: KingFX1_ETL.Transform_response manual__2024-04-13T00:20:26.090770+00:00 [queued]>
[2024-04-13T00:20:32.412+0000] {taskinstance.py:1979} INFO - Dependencies all met for dep_context=requeueable deps ti=<TaskInstance: KingFX1_ETL.Transform_response manual__2024-04-13T00:20:26.090770+00:00 [queued]>
[2024-04-13T00:20:32.413+0000] {taskinstance.py:2193} INFO - Starting attempt 1 of 1
[2024-04-13T00:20:32.429+0000] {taskinstance.py:2217} INFO - Executing <Task(PythonOperator): Transform_response> on 2024-04-13 00:20:26.090770+00:00
[2024-04-13T00:20:32.433+0000] {standard_task_runner.py:60} INFO - Started process 4413 to run task
[2024-04-13T00:20:32.436+0000] {standard_task_runner.py:87} INFO - Running: ['***', 'tasks', 'run', 'KingFX1_ETL', 'Transform_response', 'manual__2024-04-13T00:20:26.090770+00:00', '--job-id', '88', '--raw', '--subdir', 'DAGS_FOLDER/include/fx_dag.py', '--cfg-path', '/tmp/tmpxzs39win']
[2024-04-13T00:20:32.438+0000] {standard_task_runner.py:88} INFO - Job 88: Subtask Transform_response
[2024-04-13T00:20:32.485+0000] {task_command.py:423} INFO - Running <TaskInstance: KingFX1_ETL.Transform_response manual__2024-04-13T00:20:26.090770+00:00 [running]> on host 65f2ce3f86e2
[2024-04-13T00:20:32.561+0000] {taskinstance.py:2513} INFO - Exporting env vars: AIRFLOW_CTX_DAG_OWNER='***' AIRFLOW_CTX_DAG_ID='KingFX1_ETL' AIRFLOW_CTX_TASK_ID='Transform_response' AIRFLOW_CTX_EXECUTION_DATE='2024-04-13T00:20:26.090770+00:00' AIRFLOW_CTX_TRY_NUMBER='1' AIRFLOW_CTX_DAG_RUN_ID='manual__2024-04-13T00:20:26.090770+00:00'
[2024-04-13T00:20:32.562+0000] {taskinstance.py:2731} ERROR - Task failed with exception
Traceback (most recent call last):
  File "/home/airflow/.local/lib/python3.8/site-packages/airflow/models/taskinstance.py", line 444, in _execute_task
    result = _execute_callable(context=context, **execute_callable_kwargs)
  File "/home/airflow/.local/lib/python3.8/site-packages/airflow/models/taskinstance.py", line 414, in _execute_callable
    return execute_callable(context=context, **execute_callable_kwargs)
  File "/home/airflow/.local/lib/python3.8/site-packages/airflow/operators/python.py", line 200, in execute
    return_value = self.execute_callable()
  File "/home/airflow/.local/lib/python3.8/site-packages/airflow/operators/python.py", line 217, in execute_callable
    return self.python_callable(*self.op_args, **self.op_kwargs)
  File "/opt/airflow/dags/include/transform.py", line 9, in transform_data
    with open('./opt/airflow/raw/extract2.json', 'r') as json_file:
FileNotFoundError: [Errno 2] No such file or directory: './opt/airflow/raw/extract2.json'
[2024-04-13T00:20:32.575+0000] {taskinstance.py:1149} INFO - Marking task as FAILED. dag_id=KingFX1_ETL, task_id=Transform_response, execution_date=20240413T002026, start_date=20240413T002032, end_date=20240413T002032
[2024-04-13T00:20:32.587+0000] {standard_task_runner.py:107} ERROR - Failed to execute job 88 for task Transform_response ([Errno 2] No such file or directory: './opt/airflow/raw/extract2.json'; 4413)
[2024-04-13T00:20:32.609+0000] {local_task_job_runner.py:234} INFO - Task exited with return code 1
