[2024-04-16T00:39:09.228+0000] {taskinstance.py:1979} INFO - Dependencies all met for dep_context=non-requeueable deps ti=<TaskInstance: KingFX1_ETL.Extract_Response manual__2024-04-16T00:39:07.257310+00:00 [queued]>
[2024-04-16T00:39:09.236+0000] {taskinstance.py:1979} INFO - Dependencies all met for dep_context=requeueable deps ti=<TaskInstance: KingFX1_ETL.Extract_Response manual__2024-04-16T00:39:07.257310+00:00 [queued]>
[2024-04-16T00:39:09.237+0000] {taskinstance.py:2193} INFO - Starting attempt 1 of 0
[2024-04-16T00:39:09.251+0000] {taskinstance.py:2217} INFO - Executing <Task(PythonOperator): Extract_Response> on 2024-04-16 00:39:07.257310+00:00
[2024-04-16T00:39:09.255+0000] {standard_task_runner.py:60} INFO - Started process 18649 to run task
[2024-04-16T00:39:09.258+0000] {standard_task_runner.py:87} INFO - Running: ['***', 'tasks', 'run', 'KingFX1_ETL', 'Extract_Response', 'manual__2024-04-16T00:39:07.257310+00:00', '--job-id', '132', '--raw', '--subdir', 'DAGS_FOLDER/include/fx_dag.py', '--cfg-path', '/tmp/tmpiy8enizy']
[2024-04-16T00:39:09.260+0000] {standard_task_runner.py:88} INFO - Job 132: Subtask Extract_Response
[2024-04-16T00:39:09.306+0000] {task_command.py:423} INFO - Running <TaskInstance: KingFX1_ETL.Extract_Response manual__2024-04-16T00:39:07.257310+00:00 [running]> on host 65f2ce3f86e2
[2024-04-16T00:39:09.385+0000] {taskinstance.py:2513} INFO - Exporting env vars: AIRFLOW_CTX_DAG_OWNER='kresthill' AIRFLOW_CTX_DAG_ID='KingFX1_ETL' AIRFLOW_CTX_TASK_ID='Extract_Response' AIRFLOW_CTX_EXECUTION_DATE='2024-04-16T00:39:07.257310+00:00' AIRFLOW_CTX_TRY_NUMBER='1' AIRFLOW_CTX_DAG_RUN_ID='manual__2024-04-16T00:39:07.257310+00:00'
[2024-04-16T00:39:09.387+0000] {logging_mixin.py:188} INFO - datascope1000723960447 tfa78vt86qrdcgqfs5m9asp2b4
[2024-04-16T00:39:09.397+0000] {taskinstance.py:2731} ERROR - Task failed with exception
Traceback (most recent call last):
  File "/home/airflow/.local/lib/python3.8/site-packages/urllib3/connection.py", line 198, in _new_conn
    sock = connection.create_connection(
  File "/home/airflow/.local/lib/python3.8/site-packages/urllib3/util/connection.py", line 60, in create_connection
    for res in socket.getaddrinfo(host, port, family, socket.SOCK_STREAM):
  File "/usr/local/lib/python3.8/socket.py", line 918, in getaddrinfo
    for res in _socket.getaddrinfo(host, port, family, type, proto, flags):
socket.gaierror: [Errno -2] Name or service not known

The above exception was the direct cause of the following exception:

Traceback (most recent call last):
  File "/home/airflow/.local/lib/python3.8/site-packages/urllib3/connectionpool.py", line 793, in urlopen
    response = self._make_request(
  File "/home/airflow/.local/lib/python3.8/site-packages/urllib3/connectionpool.py", line 491, in _make_request
    raise new_e
  File "/home/airflow/.local/lib/python3.8/site-packages/urllib3/connectionpool.py", line 467, in _make_request
    self._validate_conn(conn)
  File "/home/airflow/.local/lib/python3.8/site-packages/urllib3/connectionpool.py", line 1099, in _validate_conn
    conn.connect()
  File "/home/airflow/.local/lib/python3.8/site-packages/urllib3/connection.py", line 616, in connect
    self.sock = sock = self._new_conn()
  File "/home/airflow/.local/lib/python3.8/site-packages/urllib3/connection.py", line 205, in _new_conn
    raise NameResolutionError(self.host, self, e) from e
urllib3.exceptions.NameResolutionError: <urllib3.connection.HTTPSConnection object at 0x7f4e7531cca0>: Failed to resolve 'xecdapi.xe.com' ([Errno -2] Name or service not known)

The above exception was the direct cause of the following exception:

Traceback (most recent call last):
  File "/home/airflow/.local/lib/python3.8/site-packages/requests/adapters.py", line 486, in send
    resp = conn.urlopen(
  File "/home/airflow/.local/lib/python3.8/site-packages/urllib3/connectionpool.py", line 847, in urlopen
    retries = retries.increment(
  File "/home/airflow/.local/lib/python3.8/site-packages/urllib3/util/retry.py", line 515, in increment
    raise MaxRetryError(_pool, url, reason) from reason  # type: ignore[arg-type]
urllib3.exceptions.MaxRetryError: HTTPSConnectionPool(host='xecdapi.xe.com', port=443): Max retries exceeded with url: /v1/convert_from.json?from=USD&to=NGN,GHS,KES,UGX,MAD,XOF,EGP (Caused by NameResolutionError("<urllib3.connection.HTTPSConnection object at 0x7f4e7531cca0>: Failed to resolve 'xecdapi.xe.com' ([Errno -2] Name or service not known)"))

During handling of the above exception, another exception occurred:

Traceback (most recent call last):
  File "/home/airflow/.local/lib/python3.8/site-packages/airflow/models/taskinstance.py", line 444, in _execute_task
    result = _execute_callable(context=context, **execute_callable_kwargs)
  File "/home/airflow/.local/lib/python3.8/site-packages/airflow/models/taskinstance.py", line 414, in _execute_callable
    return execute_callable(context=context, **execute_callable_kwargs)
  File "/home/airflow/.local/lib/python3.8/site-packages/airflow/operators/python.py", line 200, in execute
    return_value = self.execute_callable()
  File "/home/airflow/.local/lib/python3.8/site-packages/airflow/operators/python.py", line 217, in execute_callable
    return self.python_callable(*self.op_args, **self.op_kwargs)
  File "/opt/airflow/dags/include/extract.py", line 15, in extract_data
    response = requests.get(url, auth=(api_id, api_key)).json()
  File "/home/airflow/.local/lib/python3.8/site-packages/requests/api.py", line 73, in get
    return request("get", url, params=params, **kwargs)
  File "/home/airflow/.local/lib/python3.8/site-packages/requests/api.py", line 59, in request
    return session.request(method=method, url=url, **kwargs)
  File "/home/airflow/.local/lib/python3.8/site-packages/requests/sessions.py", line 589, in request
    resp = self.send(prep, **send_kwargs)
  File "/home/airflow/.local/lib/python3.8/site-packages/requests/sessions.py", line 703, in send
    r = adapter.send(request, **kwargs)
  File "/home/airflow/.local/lib/python3.8/site-packages/requests/adapters.py", line 519, in send
    raise ConnectionError(e, request=request)
requests.exceptions.ConnectionError: HTTPSConnectionPool(host='xecdapi.xe.com', port=443): Max retries exceeded with url: /v1/convert_from.json?from=USD&to=NGN,GHS,KES,UGX,MAD,XOF,EGP (Caused by NameResolutionError("<urllib3.connection.HTTPSConnection object at 0x7f4e7531cca0>: Failed to resolve 'xecdapi.xe.com' ([Errno -2] Name or service not known)"))
[2024-04-16T00:39:09.413+0000] {taskinstance.py:1149} INFO - Marking task as FAILED. dag_id=KingFX1_ETL, task_id=Extract_Response, execution_date=20240416T003907, start_date=20240416T003909, end_date=20240416T003909
[2024-04-16T00:39:09.425+0000] {standard_task_runner.py:107} ERROR - Failed to execute job 132 for task Extract_Response (HTTPSConnectionPool(host='xecdapi.xe.com', port=443): Max retries exceeded with url: /v1/convert_from.json?from=USD&to=NGN,GHS,KES,UGX,MAD,XOF,EGP (Caused by NameResolutionError("<urllib3.connection.HTTPSConnection object at 0x7f4e7531cca0>: Failed to resolve 'xecdapi.xe.com' ([Errno -2] Name or service not known)")); 18649)
[2024-04-16T00:39:09.472+0000] {local_task_job_runner.py:234} INFO - Task exited with return code 1
[2024-04-16T00:39:09.505+0000] {warnings.py:109} WARNING - /home/***/.local/lib/python3.8/site-packages/***/models/baseoperator.py:1201: AirflowProviderDeprecationWarning: Call to deprecated class SnowflakeOperator. (This class is deprecated. Please use `***.providers.common.sql.operators.sql.SQLExecuteQueryOperator`. Also, you can provide `hook_params={'warehouse': <warehouse>, 'database': <database>, 'role': <role>, 'schema': <schema>, 'authenticator': <authenticator>,'session_parameters': <session_parameters>}`.)
  result = cls.__new__(cls)

[2024-04-16T00:39:09.526+0000] {taskinstance.py:3312} INFO - 0 downstream tasks scheduled from follow-on schedule check
