[2024-04-15T22:48:41.042+0000] {taskinstance.py:1979} INFO - Dependencies all met for dep_context=non-requeueable deps ti=<TaskInstance: KingFX1_ETL.stage_data_to_snowflake manual__2024-04-15T22:48:31.180442+00:00 [queued]>
[2024-04-15T22:48:41.053+0000] {taskinstance.py:1979} INFO - Dependencies all met for dep_context=requeueable deps ti=<TaskInstance: KingFX1_ETL.stage_data_to_snowflake manual__2024-04-15T22:48:31.180442+00:00 [queued]>
[2024-04-15T22:48:41.053+0000] {taskinstance.py:2193} INFO - Starting attempt 1 of 1
[2024-04-15T22:48:41.068+0000] {taskinstance.py:2217} INFO - Executing <Task(SnowflakeOperator): stage_data_to_snowflake> on 2024-04-15 22:48:31.180442+00:00
[2024-04-15T22:48:41.073+0000] {standard_task_runner.py:60} INFO - Started process 16953 to run task
[2024-04-15T22:48:41.076+0000] {standard_task_runner.py:87} INFO - Running: ['***', 'tasks', 'run', 'KingFX1_ETL', 'stage_data_to_snowflake', 'manual__2024-04-15T22:48:31.180442+00:00', '--job-id', '114', '--raw', '--subdir', 'DAGS_FOLDER/include/fx_dag.py', '--cfg-path', '/tmp/tmpfd4p6im6']
[2024-04-15T22:48:41.079+0000] {standard_task_runner.py:88} INFO - Job 114: Subtask stage_data_to_snowflake
[2024-04-15T22:48:41.128+0000] {task_command.py:423} INFO - Running <TaskInstance: KingFX1_ETL.stage_data_to_snowflake manual__2024-04-15T22:48:31.180442+00:00 [running]> on host 65f2ce3f86e2
[2024-04-15T22:48:41.205+0000] {taskinstance.py:2513} INFO - Exporting env vars: AIRFLOW_CTX_DAG_OWNER='***' AIRFLOW_CTX_DAG_ID='KingFX1_ETL' AIRFLOW_CTX_TASK_ID='stage_data_to_snowflake' AIRFLOW_CTX_EXECUTION_DATE='2024-04-15T22:48:31.180442+00:00' AIRFLOW_CTX_TRY_NUMBER='1' AIRFLOW_CTX_DAG_RUN_ID='manual__2024-04-15T22:48:31.180442+00:00'
[2024-04-15T22:48:41.206+0000] {sql.py:276} INFO - Executing:  
        PUT file://./opt/***/raw/data.csv @~
        
[2024-04-15T22:48:41.215+0000] {base.py:83} INFO - Using connection ID 'snowflake_conn' for task execution.
[2024-04-15T22:48:41.224+0000] {base.py:83} INFO - Using connection ID 'snowflake_conn' for task execution.
[2024-04-15T22:48:41.225+0000] {connection.py:386} INFO - Snowflake Connector for Python Version: 3.7.1, Python Version: 3.8.19, Platform: Linux-5.15.146.1-microsoft-standard-WSL2-x86_64-with-glibc2.34
[2024-04-15T22:48:41.226+0000] {connection.py:1211} INFO - This connection is in OCSP Fail Open Mode. TLS Certificates would be checked for validity and revocation status. Any other Certificate Revocation related exceptions or OCSP Responder failures would be disregarded in favor of connectivity.
[2024-04-15T22:48:42.314+0000] {connection.py:547} WARNING - Certificate did not match expected hostname: fjeztio.pj12588.snowflakecomputing.com. Certificate: {'subject': ((('commonName', '*.prod3.us-west-2.snowflakecomputing.com'),),), 'subjectAltName': [('DNS', '*.prod3.us-west-2.snowflakecomputing.com'), ('DNS', '*.us-west-2.snowflakecomputing.com'), ('DNS', '*.global.snowflakecomputing.com'), ('DNS', '*.snowflakecomputing.com'), ('DNS', '*.prod3.us-west-2.aws.snowflakecomputing.com')]}
[2024-04-15T22:48:42.316+0000] {connectionpool.py:824} WARNING - Retrying (Retry(total=0, connect=None, read=None, redirect=None, status=None)) after connection broken by 'SSLError(CertificateError("hostname 'fjeztio.pj12588.snowflakecomputing.com' doesn't match either of '*.prod3.us-west-2.snowflakecomputing.com', '*.us-west-2.snowflakecomputing.com', '*.global.snowflakecomputing.com', '*.snowflakecomputing.com', '*.prod3.us-west-2.aws.snowflakecomputing.com'"))': /session/v1/login-request?request_id=f2ad6d43-eb20-45d2-a98b-aae12879bfc8&databaseName=kingsDB&schemaName=ODS&warehouse=COMPUTE_WH&roleName=ACCOUNTADMIN&request_guid=ab12d14f-4c8a-4450-9fae-9b5c7fab0148
[2024-04-15T22:48:43.381+0000] {connection.py:547} WARNING - Certificate did not match expected hostname: fjeztio.pj12588.snowflakecomputing.com. Certificate: {'subject': ((('commonName', '*.prod3.us-west-2.snowflakecomputing.com'),),), 'subjectAltName': [('DNS', '*.prod3.us-west-2.snowflakecomputing.com'), ('DNS', '*.us-west-2.snowflakecomputing.com'), ('DNS', '*.global.snowflakecomputing.com'), ('DNS', '*.snowflakecomputing.com'), ('DNS', '*.prod3.us-west-2.aws.snowflakecomputing.com')]}
[2024-04-15T22:48:43.385+0000] {network.py:1029} ERROR - Failed to get the response. Hanging? method: post, url: https://FJEZTIO.PJ12588.snowflakecomputing.com:443/session/v1/login-request?request_id=f2ad6d43-eb20-45d2-a98b-aae12879bfc8&databaseName=kingsDB&schemaName=ODS&warehouse=COMPUTE_WH&roleName=ACCOUNTADMIN&request_guid=ab12d14f-4c8a-4450-9fae-9b5c7fab0148, headers:{'Content-Type': 'application/json', 'accept': 'application/snowflake', 'User-Agent': 'PythonConnector/3.7.1 (Linux-5.15.146.1-microsoft-standard-WSL2-x86_64-with-glibc2.34) CPython/3.8.19', 'Content-Encoding': 'gzip'}, data: {"data": {"CLIENT_APP_ID": "PythonConnector", "CLIENT_APP_VERSION": "3.7.1", "SVN_REVISION": null, "ACCOUNT_NAME": "FJEZTIO", "LOGIN_NAME": "datascope1000", "CLIENT_ENVIRONMENT": {"APPLICATION": "AIRFLOW", "OS": "Linux", "OS_VERSION": "Linux-5.15.146.1-microsoft-standard-WSL2-x86_64-with-glibc2.34", "PYTHON_VERSION": "3.8.19", "PYTHON_RUNTIME": "CPython", "PYTHON_COMPILER": "GCC 12.2.0", "OCSP_MODE": "FAIL_OPEN", "TRACING": 20, "LOGIN_TIMEOUT": null, "NETWORK_TIMEOUT": null, "SOCKET_TIMEOUT": null}, "PASSWORD": "**** "SESSION_PARAMETERS": {"CLIENT_PREFETCH_THREADS": 4}}}
[2024-04-15T22:48:45.460+0000] {connection.py:547} WARNING - Certificate did not match expected hostname: fjeztio.pj12588.snowflakecomputing.com. Certificate: {'subject': ((('commonName', '*.prod3.us-west-2.snowflakecomputing.com'),),), 'subjectAltName': [('DNS', '*.prod3.us-west-2.snowflakecomputing.com'), ('DNS', '*.us-west-2.snowflakecomputing.com'), ('DNS', '*.global.snowflakecomputing.com'), ('DNS', '*.snowflakecomputing.com'), ('DNS', '*.prod3.us-west-2.aws.snowflakecomputing.com')]}
[2024-04-15T22:48:45.461+0000] {connectionpool.py:824} WARNING - Retrying (Retry(total=0, connect=None, read=None, redirect=None, status=None)) after connection broken by 'SSLError(CertificateError("hostname 'fjeztio.pj12588.snowflakecomputing.com' doesn't match either of '*.prod3.us-west-2.snowflakecomputing.com', '*.us-west-2.snowflakecomputing.com', '*.global.snowflakecomputing.com', '*.snowflakecomputing.com', '*.prod3.us-west-2.aws.snowflakecomputing.com'"))': /session/v1/login-request?request_id=8b817f87-3ba2-4a44-990b-c8af3cf04ac7&databaseName=kingsDB&schemaName=ODS&warehouse=COMPUTE_WH&roleName=ACCOUNTADMIN&request_guid=c6a57676-0513-41ad-abdd-87ec92054812
[2024-04-15T22:48:46.486+0000] {connection.py:547} WARNING - Certificate did not match expected hostname: fjeztio.pj12588.snowflakecomputing.com. Certificate: {'subject': ((('commonName', '*.prod3.us-west-2.snowflakecomputing.com'),),), 'subjectAltName': [('DNS', '*.prod3.us-west-2.snowflakecomputing.com'), ('DNS', '*.us-west-2.snowflakecomputing.com'), ('DNS', '*.global.snowflakecomputing.com'), ('DNS', '*.snowflakecomputing.com'), ('DNS', '*.prod3.us-west-2.aws.snowflakecomputing.com')]}
[2024-04-15T22:48:46.488+0000] {network.py:1029} ERROR - Failed to get the response. Hanging? method: post, url: https://FJEZTIO.PJ12588.snowflakecomputing.com:443/session/v1/login-request?request_id=8b817f87-3ba2-4a44-990b-c8af3cf04ac7&databaseName=kingsDB&schemaName=ODS&warehouse=COMPUTE_WH&roleName=ACCOUNTADMIN&request_guid=c6a57676-0513-41ad-abdd-87ec92054812, headers:{'Content-Type': 'application/json', 'accept': 'application/snowflake', 'User-Agent': 'PythonConnector/3.7.1 (Linux-5.15.146.1-microsoft-standard-WSL2-x86_64-with-glibc2.34) CPython/3.8.19', 'Content-Encoding': 'gzip'}, data: {"data": {"CLIENT_APP_ID": "PythonConnector", "CLIENT_APP_VERSION": "3.7.1", "SVN_REVISION": null, "ACCOUNT_NAME": "FJEZTIO", "LOGIN_NAME": "datascope1000", "CLIENT_ENVIRONMENT": {"APPLICATION": "AIRFLOW", "OS": "Linux", "OS_VERSION": "Linux-5.15.146.1-microsoft-standard-WSL2-x86_64-with-glibc2.34", "PYTHON_VERSION": "3.8.19", "PYTHON_RUNTIME": "CPython", "PYTHON_COMPILER": "GCC 12.2.0", "OCSP_MODE": "FAIL_OPEN", "TRACING": 20, "LOGIN_TIMEOUT": null, "NETWORK_TIMEOUT": null, "SOCKET_TIMEOUT": null}, "PASSWORD": "**** "SESSION_PARAMETERS": {"CLIENT_PREFETCH_THREADS": 4}}}
[2024-04-15T22:48:46.492+0000] {taskinstance.py:2731} ERROR - Task failed with exception
Traceback (most recent call last):
  File "/home/airflow/.local/lib/python3.8/site-packages/snowflake/connector/connection.py", line 1345, in _authenticate
    auth.authenticate(
  File "/home/airflow/.local/lib/python3.8/site-packages/snowflake/connector/auth/_auth.py", line 250, in authenticate
    ret = self._rest._post_request(
  File "/home/airflow/.local/lib/python3.8/site-packages/snowflake/connector/network.py", line 734, in _post_request
    ret = self.fetch(
  File "/home/airflow/.local/lib/python3.8/site-packages/snowflake/connector/network.py", line 843, in fetch
    ret = self._request_exec_wrapper(
  File "/home/airflow/.local/lib/python3.8/site-packages/snowflake/connector/network.py", line 979, in _request_exec_wrapper
    raise e
  File "/home/airflow/.local/lib/python3.8/site-packages/snowflake/connector/network.py", line 895, in _request_exec_wrapper
    self._handle_unknown_error(method, full_url, headers, data, conn)
  File "/home/airflow/.local/lib/python3.8/site-packages/snowflake/connector/network.py", line 1034, in _handle_unknown_error
    Error.errorhandler_wrapper(
  File "/home/airflow/.local/lib/python3.8/site-packages/snowflake/connector/errors.py", line 290, in errorhandler_wrapper
    handed_over = Error.hand_to_other_handler(
  File "/home/airflow/.local/lib/python3.8/site-packages/snowflake/connector/errors.py", line 348, in hand_to_other_handler
    connection.errorhandler(connection, cursor, error_class, error_value)
  File "/home/airflow/.local/lib/python3.8/site-packages/snowflake/connector/errors.py", line 221, in default_errorhandler
    raise error_class(
snowflake.connector.errors.OperationalError: 250003: 250003: Failed to get the response. Hanging? method: post, url: https://FJEZTIO.PJ12588.snowflakecomputing.com:443/session/v1/login-request?request_id=f2ad6d43-eb20-45d2-a98b-aae12879bfc8&databaseName=kingsDB&schemaName=ODS&warehouse=COMPUTE_WH&roleName=ACCOUNTADMIN&request_guid=ab12d14f-4c8a-4450-9fae-9b5c7fab0148

The above exception was the direct cause of the following exception:

Traceback (most recent call last):
  File "/home/airflow/.local/lib/python3.8/site-packages/airflow/models/taskinstance.py", line 444, in _execute_task
    result = _execute_callable(context=context, **execute_callable_kwargs)
  File "/home/airflow/.local/lib/python3.8/site-packages/airflow/models/taskinstance.py", line 414, in _execute_callable
    return execute_callable(context=context, **execute_callable_kwargs)
  File "/home/airflow/.local/lib/python3.8/site-packages/airflow/providers/common/sql/operators/sql.py", line 282, in execute
    output = hook.run(
  File "/home/airflow/.local/lib/python3.8/site-packages/airflow/providers/snowflake/hooks/snowflake.py", line 384, in run
    with closing(self.get_conn()) as conn:
  File "/home/airflow/.local/lib/python3.8/site-packages/airflow/providers/snowflake/hooks/snowflake.py", line 278, in get_conn
    conn = connector.connect(**conn_config)
  File "/home/airflow/.local/lib/python3.8/site-packages/snowflake/connector/__init__.py", line 54, in Connect
    return SnowflakeConnection(**kwargs)
  File "/home/airflow/.local/lib/python3.8/site-packages/snowflake/connector/connection.py", line 429, in __init__
    self.connect(**kwargs)
  File "/home/airflow/.local/lib/python3.8/site-packages/snowflake/connector/connection.py", line 719, in connect
    self.__open_connection()
  File "/home/airflow/.local/lib/python3.8/site-packages/snowflake/connector/connection.py", line 1045, in __open_connection
    self.authenticate_with_retry(self.auth_class)
  File "/home/airflow/.local/lib/python3.8/site-packages/snowflake/connector/connection.py", line 1317, in authenticate_with_retry
    self._authenticate(auth_instance)
  File "/home/airflow/.local/lib/python3.8/site-packages/snowflake/connector/connection.py", line 1389, in _authenticate
    raise auth_op from e
  File "/home/airflow/.local/lib/python3.8/site-packages/snowflake/connector/connection.py", line 1366, in _authenticate
    auth_instance.handle_timeout(
  File "/home/airflow/.local/lib/python3.8/site-packages/snowflake/connector/auth/by_plugin.py", line 212, in handle_timeout
    raise error
snowflake.connector.errors.OperationalError: 250001: 250001: Could not connect to Snowflake backend after 2 attempt(s).Aborting
[2024-04-15T22:48:46.500+0000] {taskinstance.py:1149} INFO - Marking task as FAILED. dag_id=KingFX1_ETL, task_id=stage_data_to_snowflake, execution_date=20240415T224831, start_date=20240415T224841, end_date=20240415T224846
[2024-04-15T22:48:46.515+0000] {standard_task_runner.py:107} ERROR - Failed to execute job 114 for task stage_data_to_snowflake (250001: 250001: Could not connect to Snowflake backend after 2 attempt(s).Aborting; 16953)
[2024-04-15T22:48:46.560+0000] {local_task_job_runner.py:234} INFO - Task exited with return code 1
[2024-04-15T22:48:46.569+0000] {warnings.py:109} WARNING - /home/***/.local/lib/python3.8/site-packages/***/models/baseoperator.py:1201: AirflowProviderDeprecationWarning: Call to deprecated class SnowflakeOperator. (This class is deprecated. Please use `***.providers.common.sql.operators.sql.SQLExecuteQueryOperator`. Also, you can provide `hook_params={'warehouse': <warehouse>, 'database': <database>, 'role': <role>, 'schema': <schema>, 'authenticator': <authenticator>,'session_parameters': <session_parameters>}`.)
  result = cls.__new__(cls)

[2024-04-15T22:48:46.584+0000] {taskinstance.py:3312} INFO - 0 downstream tasks scheduled from follow-on schedule check
