[2024-04-12T12:36:45.020+0000] {taskinstance.py:1979} INFO - Dependencies all met for dep_context=non-requeueable deps ti=<TaskInstance: KingFX_ETL.Extract_Response scheduled__2024-04-11T00:00:00+00:00 [queued]>
[2024-04-12T12:36:45.029+0000] {taskinstance.py:1979} INFO - Dependencies all met for dep_context=requeueable deps ti=<TaskInstance: KingFX_ETL.Extract_Response scheduled__2024-04-11T00:00:00+00:00 [queued]>
[2024-04-12T12:36:45.030+0000] {taskinstance.py:2193} INFO - Starting attempt 1 of 0
[2024-04-12T12:36:45.048+0000] {taskinstance.py:2217} INFO - Executing <Task(PythonOperator): Extract_Response> on 2024-04-11 00:00:00+00:00
[2024-04-12T12:36:45.058+0000] {standard_task_runner.py:60} INFO - Started process 8174 to run task
[2024-04-12T12:36:45.062+0000] {standard_task_runner.py:87} INFO - Running: ['***', 'tasks', 'run', 'KingFX_ETL', 'Extract_Response', 'scheduled__2024-04-11T00:00:00+00:00', '--job-id', '16', '--raw', '--subdir', 'DAGS_FOLDER/include/fx_dag.py', '--cfg-path', '/tmp/tmpugjto4tl']
[2024-04-12T12:36:45.065+0000] {standard_task_runner.py:88} INFO - Job 16: Subtask Extract_Response
[2024-04-12T12:36:45.119+0000] {task_command.py:423} INFO - Running <TaskInstance: KingFX_ETL.Extract_Response scheduled__2024-04-11T00:00:00+00:00 [running]> on host ab7b3f965e72
[2024-04-12T12:36:45.200+0000] {taskinstance.py:2513} INFO - Exporting env vars: AIRFLOW_CTX_DAG_OWNER='kresthill' AIRFLOW_CTX_DAG_ID='KingFX_ETL' AIRFLOW_CTX_TASK_ID='Extract_Response' AIRFLOW_CTX_EXECUTION_DATE='2024-04-11T00:00:00+00:00' AIRFLOW_CTX_TRY_NUMBER='1' AIRFLOW_CTX_DAG_RUN_ID='scheduled__2024-04-11T00:00:00+00:00'
[2024-04-12T12:36:53.208+0000] {taskinstance.py:2731} ERROR - Task failed with exception
Traceback (most recent call last):
  File "/home/airflow/.local/lib/python3.8/site-packages/urllib3/connection.py", line 198, in _new_conn
    sock = connection.create_connection(
  File "/home/airflow/.local/lib/python3.8/site-packages/urllib3/util/connection.py", line 60, in create_connection
    for res in socket.getaddrinfo(host, port, family, socket.SOCK_STREAM):
  File "/usr/local/lib/python3.8/socket.py", line 918, in getaddrinfo
    for res in _socket.getaddrinfo(host, port, family, type, proto, flags):
socket.gaierror: [Errno -3] Temporary failure in name resolution

The above exception was the direct cause of the following exception:

Traceback (most recent call last):
  File "/home/airflow/.local/lib/python3.8/site-packages/urllib3/connectionpool.py", line 793, in urlopen
    response = self._make_request(
  File "/home/airflow/.local/lib/python3.8/site-packages/urllib3/connectionpool.py", line 491, in _make_request
    raise new_e
  File "/home/airflow/.local/lib/python3.8/site-packages/urllib3/connectionpool.py", line 467, in _make_request
    self._validate_conn(conn)
  File "/home/airflow/.local/lib/python3.8/site-packages/urllib3/connectionpool.py", line 1099, in _validate_conn
    conn.connect()
  File "/home/airflow/.local/lib/python3.8/site-packages/urllib3/connection.py", line 616, in connect
    self.sock = sock = self._new_conn()
  File "/home/airflow/.local/lib/python3.8/site-packages/urllib3/connection.py", line 205, in _new_conn
    raise NameResolutionError(self.host, self, e) from e
urllib3.exceptions.NameResolutionError: <urllib3.connection.HTTPSConnection object at 0x7f3156413370>: Failed to resolve 'xecdapi.xe.com' ([Errno -3] Temporary failure in name resolution)

The above exception was the direct cause of the following exception:

Traceback (most recent call last):
  File "/home/airflow/.local/lib/python3.8/site-packages/requests/adapters.py", line 486, in send
    resp = conn.urlopen(
  File "/home/airflow/.local/lib/python3.8/site-packages/urllib3/connectionpool.py", line 847, in urlopen
    retries = retries.increment(
  File "/home/airflow/.local/lib/python3.8/site-packages/urllib3/util/retry.py", line 515, in increment
    raise MaxRetryError(_pool, url, reason) from reason  # type: ignore[arg-type]
urllib3.exceptions.MaxRetryError: HTTPSConnectionPool(host='xecdapi.xe.com', port=443): Max retries exceeded with url: /v1/convert_from.json/?from=USD&to=NGN,GHS,KES,UGX,MAD,XOF,EGP*&amount=1 (Caused by NameResolutionError("<urllib3.connection.HTTPSConnection object at 0x7f3156413370>: Failed to resolve 'xecdapi.xe.com' ([Errno -3] Temporary failure in name resolution)"))

During handling of the above exception, another exception occurred:

Traceback (most recent call last):
  File "/home/airflow/.local/lib/python3.8/site-packages/airflow/models/taskinstance.py", line 444, in _execute_task
    result = _execute_callable(context=context, **execute_callable_kwargs)
  File "/home/airflow/.local/lib/python3.8/site-packages/airflow/models/taskinstance.py", line 414, in _execute_callable
    return execute_callable(context=context, **execute_callable_kwargs)
  File "/home/airflow/.local/lib/python3.8/site-packages/airflow/operators/python.py", line 200, in execute
    return_value = self.execute_callable()
  File "/home/airflow/.local/lib/python3.8/site-packages/airflow/operators/python.py", line 217, in execute_callable
    return self.python_callable(*self.op_args, **self.op_kwargs)
  File "/opt/airflow/dags/include/extract.py", line 22, in extract_data
    response = requests.get(url, auth=(api_id, api_key)).json()
  File "/home/airflow/.local/lib/python3.8/site-packages/requests/api.py", line 73, in get
    return request("get", url, params=params, **kwargs)
  File "/home/airflow/.local/lib/python3.8/site-packages/requests/api.py", line 59, in request
    return session.request(method=method, url=url, **kwargs)
  File "/home/airflow/.local/lib/python3.8/site-packages/requests/sessions.py", line 589, in request
    resp = self.send(prep, **send_kwargs)
  File "/home/airflow/.local/lib/python3.8/site-packages/requests/sessions.py", line 703, in send
    r = adapter.send(request, **kwargs)
  File "/home/airflow/.local/lib/python3.8/site-packages/requests/adapters.py", line 519, in send
    raise ConnectionError(e, request=request)
requests.exceptions.ConnectionError: HTTPSConnectionPool(host='xecdapi.xe.com', port=443): Max retries exceeded with url: /v1/convert_from.json/?from=USD&to=NGN,GHS,KES,UGX,MAD,XOF,EGP*&amount=1 (Caused by NameResolutionError("<urllib3.connection.HTTPSConnection object at 0x7f3156413370>: Failed to resolve 'xecdapi.xe.com' ([Errno -3] Temporary failure in name resolution)"))
[2024-04-12T12:36:53.223+0000] {taskinstance.py:1149} INFO - Marking task as FAILED. dag_id=KingFX_ETL, task_id=Extract_Response, execution_date=20240411T000000, start_date=20240412T123645, end_date=20240412T123653
[2024-04-12T12:36:53.236+0000] {standard_task_runner.py:107} ERROR - Failed to execute job 16 for task Extract_Response (HTTPSConnectionPool(host='xecdapi.xe.com', port=443): Max retries exceeded with url: /v1/convert_from.json/?from=USD&to=NGN,GHS,KES,UGX,MAD,XOF,EGP*&amount=1 (Caused by NameResolutionError("<urllib3.connection.HTTPSConnection object at 0x7f3156413370>: Failed to resolve 'xecdapi.xe.com' ([Errno -3] Temporary failure in name resolution)")); 8174)
[2024-04-12T12:36:53.271+0000] {local_task_job_runner.py:234} INFO - Task exited with return code 1
[2024-04-12T14:40:07.877+0000] {taskinstance.py:1979} INFO - Dependencies all met for dep_context=non-requeueable deps ti=<TaskInstance: KingFX_ETL.Extract_Response scheduled__2024-04-11T00:00:00+00:00 [queued]>
[2024-04-12T14:40:07.886+0000] {taskinstance.py:1979} INFO - Dependencies all met for dep_context=requeueable deps ti=<TaskInstance: KingFX_ETL.Extract_Response scheduled__2024-04-11T00:00:00+00:00 [queued]>
[2024-04-12T14:40:07.887+0000] {taskinstance.py:2193} INFO - Starting attempt 1 of 0
[2024-04-12T14:40:07.903+0000] {taskinstance.py:2217} INFO - Executing <Task(PythonOperator): Extract_Response> on 2024-04-11 00:00:00+00:00
[2024-04-12T14:40:07.912+0000] {standard_task_runner.py:60} INFO - Started process 10040 to run task
[2024-04-12T14:40:07.917+0000] {standard_task_runner.py:87} INFO - Running: ['***', 'tasks', 'run', 'KingFX_ETL', 'Extract_Response', 'scheduled__2024-04-11T00:00:00+00:00', '--job-id', '23', '--raw', '--subdir', 'DAGS_FOLDER/include/fx_dag.py', '--cfg-path', '/tmp/tmp6l1n37bm']
[2024-04-12T14:40:07.920+0000] {standard_task_runner.py:88} INFO - Job 23: Subtask Extract_Response
[2024-04-12T14:40:07.979+0000] {task_command.py:423} INFO - Running <TaskInstance: KingFX_ETL.Extract_Response scheduled__2024-04-11T00:00:00+00:00 [running]> on host ab7b3f965e72
[2024-04-12T14:40:08.059+0000] {taskinstance.py:2513} INFO - Exporting env vars: AIRFLOW_CTX_DAG_OWNER='kresthill' AIRFLOW_CTX_DAG_ID='KingFX_ETL' AIRFLOW_CTX_TASK_ID='Extract_Response' AIRFLOW_CTX_EXECUTION_DATE='2024-04-11T00:00:00+00:00' AIRFLOW_CTX_TRY_NUMBER='1' AIRFLOW_CTX_DAG_RUN_ID='scheduled__2024-04-11T00:00:00+00:00'
[2024-04-12T14:40:09.524+0000] {logging_mixin.py:188} INFO - {'code': 1, 'message': 'Bad credentials', 'documentation_url': 'https://xecdapi.xe.com/docs/v1/'}
[2024-04-12T14:40:09.525+0000] {python.py:202} INFO - Done. Returned value was: None
[2024-04-12T14:40:09.534+0000] {taskinstance.py:1149} INFO - Marking task as SUCCESS. dag_id=KingFX_ETL, task_id=Extract_Response, execution_date=20240411T000000, start_date=20240412T144007, end_date=20240412T144009
[2024-04-12T14:40:09.578+0000] {local_task_job_runner.py:234} INFO - Task exited with return code 0
[2024-04-12T19:46:25.010+0000] {taskinstance.py:1979} INFO - Dependencies all met for dep_context=non-requeueable deps ti=<TaskInstance: KingFX_ETL.Extract_Response scheduled__2024-04-11T00:00:00+00:00 [queued]>
[2024-04-12T19:46:25.020+0000] {taskinstance.py:1979} INFO - Dependencies all met for dep_context=requeueable deps ti=<TaskInstance: KingFX_ETL.Extract_Response scheduled__2024-04-11T00:00:00+00:00 [queued]>
[2024-04-12T19:46:25.021+0000] {taskinstance.py:2193} INFO - Starting attempt 1 of 0
[2024-04-12T19:46:25.034+0000] {taskinstance.py:2217} INFO - Executing <Task(PythonOperator): Extract_Response> on 2024-04-11 00:00:00+00:00
[2024-04-12T19:46:25.038+0000] {standard_task_runner.py:60} INFO - Started process 163 to run task
[2024-04-12T19:46:25.041+0000] {standard_task_runner.py:87} INFO - Running: ['***', 'tasks', 'run', 'KingFX_ETL', 'Extract_Response', 'scheduled__2024-04-11T00:00:00+00:00', '--job-id', '36', '--raw', '--subdir', 'DAGS_FOLDER/include/fx_dag.py', '--cfg-path', '/tmp/tmpw7vixn3q']
[2024-04-12T19:46:25.045+0000] {standard_task_runner.py:88} INFO - Job 36: Subtask Extract_Response
[2024-04-12T19:46:25.094+0000] {task_command.py:423} INFO - Running <TaskInstance: KingFX_ETL.Extract_Response scheduled__2024-04-11T00:00:00+00:00 [running]> on host 65f2ce3f86e2
[2024-04-12T19:46:25.167+0000] {taskinstance.py:2513} INFO - Exporting env vars: AIRFLOW_CTX_DAG_OWNER='kresthill' AIRFLOW_CTX_DAG_ID='KingFX_ETL' AIRFLOW_CTX_TASK_ID='Extract_Response' AIRFLOW_CTX_EXECUTION_DATE='2024-04-11T00:00:00+00:00' AIRFLOW_CTX_TRY_NUMBER='1' AIRFLOW_CTX_DAG_RUN_ID='scheduled__2024-04-11T00:00:00+00:00'
[2024-04-12T19:46:26.503+0000] {logging_mixin.py:188} INFO - {'code': 1, 'message': 'Bad credentials', 'documentation_url': 'https://xecdapi.xe.com/docs/v1/'}
[2024-04-12T19:46:26.505+0000] {python.py:202} INFO - Done. Returned value was: None
[2024-04-12T19:46:26.514+0000] {taskinstance.py:1149} INFO - Marking task as SUCCESS. dag_id=KingFX_ETL, task_id=Extract_Response, execution_date=20240411T000000, start_date=20240412T194625, end_date=20240412T194626
[2024-04-12T19:46:26.546+0000] {local_task_job_runner.py:234} INFO - Task exited with return code 0
[2024-04-12T20:23:09.967+0000] {taskinstance.py:1979} INFO - Dependencies all met for dep_context=non-requeueable deps ti=<TaskInstance: KingFX_ETL.Extract_Response scheduled__2024-04-11T00:00:00+00:00 [queued]>
[2024-04-12T20:23:09.976+0000] {taskinstance.py:1979} INFO - Dependencies all met for dep_context=requeueable deps ti=<TaskInstance: KingFX_ETL.Extract_Response scheduled__2024-04-11T00:00:00+00:00 [queued]>
[2024-04-12T20:23:09.976+0000] {taskinstance.py:2193} INFO - Starting attempt 1 of 0
[2024-04-12T20:23:09.993+0000] {taskinstance.py:2217} INFO - Executing <Task(PythonOperator): Extract_Response> on 2024-04-11 00:00:00+00:00
[2024-04-12T20:23:09.998+0000] {standard_task_runner.py:60} INFO - Started process 741 to run task
[2024-04-12T20:23:10.002+0000] {standard_task_runner.py:87} INFO - Running: ['***', 'tasks', 'run', 'KingFX_ETL', 'Extract_Response', 'scheduled__2024-04-11T00:00:00+00:00', '--job-id', '43', '--raw', '--subdir', 'DAGS_FOLDER/include/fx_dag.py', '--cfg-path', '/tmp/tmprxd_x2oi']
[2024-04-12T20:23:10.004+0000] {standard_task_runner.py:88} INFO - Job 43: Subtask Extract_Response
[2024-04-12T20:23:10.057+0000] {task_command.py:423} INFO - Running <TaskInstance: KingFX_ETL.Extract_Response scheduled__2024-04-11T00:00:00+00:00 [running]> on host 65f2ce3f86e2
[2024-04-12T20:23:10.132+0000] {taskinstance.py:2513} INFO - Exporting env vars: AIRFLOW_CTX_DAG_OWNER='kresthill' AIRFLOW_CTX_DAG_ID='KingFX_ETL' AIRFLOW_CTX_TASK_ID='Extract_Response' AIRFLOW_CTX_EXECUTION_DATE='2024-04-11T00:00:00+00:00' AIRFLOW_CTX_TRY_NUMBER='1' AIRFLOW_CTX_DAG_RUN_ID='scheduled__2024-04-11T00:00:00+00:00'
[2024-04-12T20:23:11.950+0000] {logging_mixin.py:188} INFO - {'code': 1, 'message': 'Bad credentials', 'documentation_url': 'https://xecdapi.xe.com/docs/v1/'}
[2024-04-12T20:23:11.951+0000] {python.py:202} INFO - Done. Returned value was: None
[2024-04-12T20:23:11.964+0000] {taskinstance.py:1149} INFO - Marking task as SUCCESS. dag_id=KingFX_ETL, task_id=Extract_Response, execution_date=20240411T000000, start_date=20240412T202309, end_date=20240412T202311
[2024-04-12T20:23:12.029+0000] {local_task_job_runner.py:234} INFO - Task exited with return code 0
[2024-04-12T21:36:13.835+0000] {taskinstance.py:1979} INFO - Dependencies all met for dep_context=non-requeueable deps ti=<TaskInstance: KingFX_ETL.Extract_Response scheduled__2024-04-11T00:00:00+00:00 [queued]>
[2024-04-12T21:36:13.844+0000] {taskinstance.py:1979} INFO - Dependencies all met for dep_context=requeueable deps ti=<TaskInstance: KingFX_ETL.Extract_Response scheduled__2024-04-11T00:00:00+00:00 [queued]>
[2024-04-12T21:36:13.845+0000] {taskinstance.py:2193} INFO - Starting attempt 1 of 0
[2024-04-12T21:36:13.860+0000] {taskinstance.py:2217} INFO - Executing <Task(PythonOperator): Extract_Response> on 2024-04-11 00:00:00+00:00
[2024-04-12T21:36:13.865+0000] {standard_task_runner.py:60} INFO - Started process 1842 to run task
[2024-04-12T21:36:13.867+0000] {standard_task_runner.py:87} INFO - Running: ['***', 'tasks', 'run', 'KingFX_ETL', 'Extract_Response', 'scheduled__2024-04-11T00:00:00+00:00', '--job-id', '47', '--raw', '--subdir', 'DAGS_FOLDER/include/fx_dag.py', '--cfg-path', '/tmp/tmpu9zepdt4']
[2024-04-12T21:36:13.870+0000] {standard_task_runner.py:88} INFO - Job 47: Subtask Extract_Response
[2024-04-12T21:36:13.916+0000] {task_command.py:423} INFO - Running <TaskInstance: KingFX_ETL.Extract_Response scheduled__2024-04-11T00:00:00+00:00 [running]> on host 65f2ce3f86e2
[2024-04-12T21:36:14.008+0000] {taskinstance.py:2513} INFO - Exporting env vars: AIRFLOW_CTX_DAG_OWNER='kresthill' AIRFLOW_CTX_DAG_ID='KingFX_ETL' AIRFLOW_CTX_TASK_ID='Extract_Response' AIRFLOW_CTX_EXECUTION_DATE='2024-04-11T00:00:00+00:00' AIRFLOW_CTX_TRY_NUMBER='1' AIRFLOW_CTX_DAG_RUN_ID='scheduled__2024-04-11T00:00:00+00:00'
[2024-04-12T21:36:15.615+0000] {logging_mixin.py:188} INFO - {'code': 1, 'message': 'Bad credentials', 'documentation_url': 'https://xecdapi.xe.com/docs/v1/'}
[2024-04-12T21:36:15.616+0000] {python.py:202} INFO - Done. Returned value was: None
[2024-04-12T21:36:15.625+0000] {taskinstance.py:1149} INFO - Marking task as SUCCESS. dag_id=KingFX_ETL, task_id=Extract_Response, execution_date=20240411T000000, start_date=20240412T213613, end_date=20240412T213615
[2024-04-12T21:36:15.654+0000] {local_task_job_runner.py:234} INFO - Task exited with return code 0
[2024-04-12T22:02:04.474+0000] {taskinstance.py:1979} INFO - Dependencies all met for dep_context=non-requeueable deps ti=<TaskInstance: KingFX_ETL.Extract_Response scheduled__2024-04-11T00:00:00+00:00 [queued]>
[2024-04-12T22:02:04.482+0000] {taskinstance.py:1979} INFO - Dependencies all met for dep_context=requeueable deps ti=<TaskInstance: KingFX_ETL.Extract_Response scheduled__2024-04-11T00:00:00+00:00 [queued]>
[2024-04-12T22:02:04.483+0000] {taskinstance.py:2193} INFO - Starting attempt 1 of 0
[2024-04-12T22:02:04.497+0000] {taskinstance.py:2217} INFO - Executing <Task(PythonOperator): Extract_Response> on 2024-04-11 00:00:00+00:00
[2024-04-12T22:02:04.502+0000] {standard_task_runner.py:60} INFO - Started process 2263 to run task
[2024-04-12T22:02:04.505+0000] {standard_task_runner.py:87} INFO - Running: ['***', 'tasks', 'run', 'KingFX_ETL', 'Extract_Response', 'scheduled__2024-04-11T00:00:00+00:00', '--job-id', '60', '--raw', '--subdir', 'DAGS_FOLDER/include/fx_dag.py', '--cfg-path', '/tmp/tmp49ox_sd2']
[2024-04-12T22:02:04.508+0000] {standard_task_runner.py:88} INFO - Job 60: Subtask Extract_Response
[2024-04-12T22:02:04.561+0000] {task_command.py:423} INFO - Running <TaskInstance: KingFX_ETL.Extract_Response scheduled__2024-04-11T00:00:00+00:00 [running]> on host 65f2ce3f86e2
[2024-04-12T22:02:04.634+0000] {taskinstance.py:2513} INFO - Exporting env vars: AIRFLOW_CTX_DAG_OWNER='kresthill' AIRFLOW_CTX_DAG_ID='KingFX_ETL' AIRFLOW_CTX_TASK_ID='Extract_Response' AIRFLOW_CTX_EXECUTION_DATE='2024-04-11T00:00:00+00:00' AIRFLOW_CTX_TRY_NUMBER='1' AIRFLOW_CTX_DAG_RUN_ID='scheduled__2024-04-11T00:00:00+00:00'
[2024-04-12T22:02:05.707+0000] {logging_mixin.py:188} INFO - {'code': 1, 'message': 'Bad credentials', 'documentation_url': 'https://xecdapi.xe.com/docs/v1/'}
[2024-04-12T22:02:05.709+0000] {python.py:202} INFO - Done. Returned value was: None
[2024-04-12T22:02:05.732+0000] {taskinstance.py:1149} INFO - Marking task as SUCCESS. dag_id=KingFX_ETL, task_id=Extract_Response, execution_date=20240411T000000, start_date=20240412T220204, end_date=20240412T220205
[2024-04-12T22:02:05.768+0000] {local_task_job_runner.py:234} INFO - Task exited with return code 0
[2024-04-12T22:36:23.229+0000] {taskinstance.py:1979} INFO - Dependencies all met for dep_context=non-requeueable deps ti=<TaskInstance: KingFX_ETL.Extract_Response scheduled__2024-04-11T00:00:00+00:00 [queued]>
[2024-04-12T22:36:23.237+0000] {taskinstance.py:1979} INFO - Dependencies all met for dep_context=requeueable deps ti=<TaskInstance: KingFX_ETL.Extract_Response scheduled__2024-04-11T00:00:00+00:00 [queued]>
[2024-04-12T22:36:23.237+0000] {taskinstance.py:2193} INFO - Starting attempt 1 of 0
[2024-04-12T22:36:23.250+0000] {taskinstance.py:2217} INFO - Executing <Task(PythonOperator): Extract_Response> on 2024-04-11 00:00:00+00:00
[2024-04-12T22:36:23.255+0000] {standard_task_runner.py:60} INFO - Started process 2800 to run task
[2024-04-12T22:36:23.258+0000] {standard_task_runner.py:87} INFO - Running: ['***', 'tasks', 'run', 'KingFX_ETL', 'Extract_Response', 'scheduled__2024-04-11T00:00:00+00:00', '--job-id', '67', '--raw', '--subdir', 'DAGS_FOLDER/include/fx_dag.py', '--cfg-path', '/tmp/tmpn6r4pmjc']
[2024-04-12T22:36:23.261+0000] {standard_task_runner.py:88} INFO - Job 67: Subtask Extract_Response
[2024-04-12T22:36:23.312+0000] {task_command.py:423} INFO - Running <TaskInstance: KingFX_ETL.Extract_Response scheduled__2024-04-11T00:00:00+00:00 [running]> on host 65f2ce3f86e2
[2024-04-12T22:36:23.384+0000] {taskinstance.py:2513} INFO - Exporting env vars: AIRFLOW_CTX_DAG_OWNER='kresthill' AIRFLOW_CTX_DAG_ID='KingFX_ETL' AIRFLOW_CTX_TASK_ID='Extract_Response' AIRFLOW_CTX_EXECUTION_DATE='2024-04-11T00:00:00+00:00' AIRFLOW_CTX_TRY_NUMBER='1' AIRFLOW_CTX_DAG_RUN_ID='scheduled__2024-04-11T00:00:00+00:00'
[2024-04-12T22:36:23.386+0000] {logging_mixin.py:188} INFO - tfa78vt86qrdcgqfs5m9asp2b4 datascope1000723960447
[2024-04-12T22:36:24.707+0000] {logging_mixin.py:188} INFO - {'code': 1, 'message': 'Bad credentials', 'documentation_url': 'https://xecdapi.xe.com/docs/v1/'}
[2024-04-12T22:36:24.708+0000] {python.py:202} INFO - Done. Returned value was: None
[2024-04-12T22:36:24.717+0000] {taskinstance.py:1149} INFO - Marking task as SUCCESS. dag_id=KingFX_ETL, task_id=Extract_Response, execution_date=20240411T000000, start_date=20240412T223623, end_date=20240412T223624
[2024-04-12T22:36:24.764+0000] {local_task_job_runner.py:234} INFO - Task exited with return code 0
