[2024-04-12T14:40:11.374+0000] {taskinstance.py:1979} INFO - Dependencies all met for dep_context=non-requeueable deps ti=<TaskInstance: KingFX_ETL.Transform_Response manual__2024-04-12T14:40:03.622338+00:00 [queued]>
[2024-04-12T14:40:11.385+0000] {taskinstance.py:1979} INFO - Dependencies all met for dep_context=requeueable deps ti=<TaskInstance: KingFX_ETL.Transform_Response manual__2024-04-12T14:40:03.622338+00:00 [queued]>
[2024-04-12T14:40:11.386+0000] {taskinstance.py:2193} INFO - Starting attempt 1 of 1
[2024-04-12T14:40:11.404+0000] {taskinstance.py:2217} INFO - Executing <Task(PythonOperator): Transform_Response> on 2024-04-12 14:40:03.622338+00:00
[2024-04-12T14:40:11.410+0000] {standard_task_runner.py:60} INFO - Started process 10054 to run task
[2024-04-12T14:40:11.413+0000] {standard_task_runner.py:87} INFO - Running: ['***', 'tasks', 'run', 'KingFX_ETL', 'Transform_Response', 'manual__2024-04-12T14:40:03.622338+00:00', '--job-id', '25', '--raw', '--subdir', 'DAGS_FOLDER/include/fx_dag.py', '--cfg-path', '/tmp/tmp8w6i9fmj']
[2024-04-12T14:40:11.417+0000] {standard_task_runner.py:88} INFO - Job 25: Subtask Transform_Response
[2024-04-12T14:40:11.468+0000] {task_command.py:423} INFO - Running <TaskInstance: KingFX_ETL.Transform_Response manual__2024-04-12T14:40:03.622338+00:00 [running]> on host ab7b3f965e72
[2024-04-12T14:40:11.547+0000] {taskinstance.py:2513} INFO - Exporting env vars: AIRFLOW_CTX_DAG_OWNER='***' AIRFLOW_CTX_DAG_ID='KingFX_ETL' AIRFLOW_CTX_TASK_ID='Transform_Response' AIRFLOW_CTX_EXECUTION_DATE='2024-04-12T14:40:03.622338+00:00' AIRFLOW_CTX_TRY_NUMBER='1' AIRFLOW_CTX_DAG_RUN_ID='manual__2024-04-12T14:40:03.622338+00:00'
[2024-04-12T14:40:11.549+0000] {taskinstance.py:2731} ERROR - Task failed with exception
Traceback (most recent call last):
  File "/home/airflow/.local/lib/python3.8/site-packages/airflow/models/taskinstance.py", line 444, in _execute_task
    result = _execute_callable(context=context, **execute_callable_kwargs)
  File "/home/airflow/.local/lib/python3.8/site-packages/airflow/models/taskinstance.py", line 414, in _execute_callable
    return execute_callable(context=context, **execute_callable_kwargs)
  File "/home/airflow/.local/lib/python3.8/site-packages/airflow/operators/python.py", line 200, in execute
    return_value = self.execute_callable()
  File "/home/airflow/.local/lib/python3.8/site-packages/airflow/operators/python.py", line 217, in execute_callable
    return self.python_callable(*self.op_args, **self.op_kwargs)
TypeError: transform_data() missing 1 required positional argument: 'data'
[2024-04-12T14:40:11.559+0000] {taskinstance.py:1149} INFO - Marking task as FAILED. dag_id=KingFX_ETL, task_id=Transform_Response, execution_date=20240412T144003, start_date=20240412T144011, end_date=20240412T144011
[2024-04-12T14:40:11.574+0000] {standard_task_runner.py:107} ERROR - Failed to execute job 25 for task Transform_Response (transform_data() missing 1 required positional argument: 'data'; 10054)
[2024-04-12T14:40:11.586+0000] {local_task_job_runner.py:234} INFO - Task exited with return code 1
