[2024-04-12T12:38:16.788+0000] {taskinstance.py:1979} INFO - Dependencies all met for dep_context=non-requeueable deps ti=<TaskInstance: KingFX_ETL.Transform_Response manual__2024-04-12T12:38:10.822124+00:00 [queued]>
[2024-04-12T12:38:16.798+0000] {taskinstance.py:1979} INFO - Dependencies all met for dep_context=requeueable deps ti=<TaskInstance: KingFX_ETL.Transform_Response manual__2024-04-12T12:38:10.822124+00:00 [queued]>
[2024-04-12T12:38:16.799+0000] {taskinstance.py:2193} INFO - Starting attempt 1 of 1
[2024-04-12T12:38:16.819+0000] {taskinstance.py:2217} INFO - Executing <Task(PythonOperator): Transform_Response> on 2024-04-12 12:38:10.822124+00:00
[2024-04-12T12:38:16.824+0000] {standard_task_runner.py:60} INFO - Started process 8204 to run task
[2024-04-12T12:38:16.827+0000] {standard_task_runner.py:87} INFO - Running: ['***', 'tasks', 'run', 'KingFX_ETL', 'Transform_Response', 'manual__2024-04-12T12:38:10.822124+00:00', '--job-id', '18', '--raw', '--subdir', 'DAGS_FOLDER/include/fx_dag.py', '--cfg-path', '/tmp/tmp5e37u8ao']
[2024-04-12T12:38:16.830+0000] {standard_task_runner.py:88} INFO - Job 18: Subtask Transform_Response
[2024-04-12T12:38:16.878+0000] {task_command.py:423} INFO - Running <TaskInstance: KingFX_ETL.Transform_Response manual__2024-04-12T12:38:10.822124+00:00 [running]> on host ab7b3f965e72
[2024-04-12T12:38:16.946+0000] {taskinstance.py:2513} INFO - Exporting env vars: AIRFLOW_CTX_DAG_OWNER='***' AIRFLOW_CTX_DAG_ID='KingFX_ETL' AIRFLOW_CTX_TASK_ID='Transform_Response' AIRFLOW_CTX_EXECUTION_DATE='2024-04-12T12:38:10.822124+00:00' AIRFLOW_CTX_TRY_NUMBER='1' AIRFLOW_CTX_DAG_RUN_ID='manual__2024-04-12T12:38:10.822124+00:00'
[2024-04-12T12:38:16.948+0000] {taskinstance.py:2731} ERROR - Task failed with exception
Traceback (most recent call last):
  File "/home/airflow/.local/lib/python3.8/site-packages/airflow/models/taskinstance.py", line 444, in _execute_task
    result = _execute_callable(context=context, **execute_callable_kwargs)
  File "/home/airflow/.local/lib/python3.8/site-packages/airflow/models/taskinstance.py", line 414, in _execute_callable
    return execute_callable(context=context, **execute_callable_kwargs)
  File "/home/airflow/.local/lib/python3.8/site-packages/airflow/operators/python.py", line 200, in execute
    return_value = self.execute_callable()
  File "/home/airflow/.local/lib/python3.8/site-packages/airflow/operators/python.py", line 217, in execute_callable
    return self.python_callable(*self.op_args, **self.op_kwargs)
TypeError: transform_data() missing 1 required positional argument: 'data'
[2024-04-12T12:38:16.955+0000] {taskinstance.py:1149} INFO - Marking task as FAILED. dag_id=KingFX_ETL, task_id=Transform_Response, execution_date=20240412T123810, start_date=20240412T123816, end_date=20240412T123816
[2024-04-12T12:38:16.965+0000] {standard_task_runner.py:107} ERROR - Failed to execute job 18 for task Transform_Response (transform_data() missing 1 required positional argument: 'data'; 8204)
[2024-04-12T12:38:17.000+0000] {local_task_job_runner.py:234} INFO - Task exited with return code 1
