[2024-04-12T12:48:29.979+0000] {taskinstance.py:1979} INFO - Dependencies all met for dep_context=non-requeueable deps ti=<TaskInstance: KingFX_ETL.Extract_Response manual__2024-04-12T12:48:28.423665+00:00 [queued]>
[2024-04-12T12:48:29.987+0000] {taskinstance.py:1979} INFO - Dependencies all met for dep_context=requeueable deps ti=<TaskInstance: KingFX_ETL.Extract_Response manual__2024-04-12T12:48:28.423665+00:00 [queued]>
[2024-04-12T12:48:29.988+0000] {taskinstance.py:2193} INFO - Starting attempt 1 of 0
[2024-04-12T12:48:30.003+0000] {taskinstance.py:2217} INFO - Executing <Task(PythonOperator): Extract_Response> on 2024-04-12 12:48:28.423665+00:00
[2024-04-12T12:48:30.008+0000] {standard_task_runner.py:60} INFO - Started process 8364 to run task
[2024-04-12T12:48:30.013+0000] {standard_task_runner.py:87} INFO - Running: ['***', 'tasks', 'run', 'KingFX_ETL', 'Extract_Response', 'manual__2024-04-12T12:48:28.423665+00:00', '--job-id', '20', '--raw', '--subdir', 'DAGS_FOLDER/include/fx_dag.py', '--cfg-path', '/tmp/tmpa4l_h_ez']
[2024-04-12T12:48:30.020+0000] {standard_task_runner.py:88} INFO - Job 20: Subtask Extract_Response
[2024-04-12T12:48:30.085+0000] {task_command.py:423} INFO - Running <TaskInstance: KingFX_ETL.Extract_Response manual__2024-04-12T12:48:28.423665+00:00 [running]> on host ab7b3f965e72
[2024-04-12T12:48:30.178+0000] {taskinstance.py:2513} INFO - Exporting env vars: AIRFLOW_CTX_DAG_OWNER='kresthill' AIRFLOW_CTX_DAG_ID='KingFX_ETL' AIRFLOW_CTX_TASK_ID='Extract_Response' AIRFLOW_CTX_EXECUTION_DATE='2024-04-12T12:48:28.423665+00:00' AIRFLOW_CTX_TRY_NUMBER='1' AIRFLOW_CTX_DAG_RUN_ID='manual__2024-04-12T12:48:28.423665+00:00'
[2024-04-12T12:48:51.612+0000] {taskinstance.py:2731} ERROR - Task failed with exception
Traceback (most recent call last):
  File "/home/airflow/.local/lib/python3.8/site-packages/urllib3/connectionpool.py", line 467, in _make_request
    self._validate_conn(conn)
  File "/home/airflow/.local/lib/python3.8/site-packages/urllib3/connectionpool.py", line 1099, in _validate_conn
    conn.connect()
  File "/home/airflow/.local/lib/python3.8/site-packages/urllib3/connection.py", line 653, in connect
    sock_and_verified = _ssl_wrap_socket_and_match_hostname(
  File "/home/airflow/.local/lib/python3.8/site-packages/urllib3/connection.py", line 806, in _ssl_wrap_socket_and_match_hostname
    ssl_sock = ssl_wrap_socket(
  File "/home/airflow/.local/lib/python3.8/site-packages/urllib3/util/ssl_.py", line 465, in ssl_wrap_socket
    ssl_sock = _ssl_wrap_socket_impl(sock, context, tls_in_tls, server_hostname)
  File "/home/airflow/.local/lib/python3.8/site-packages/urllib3/util/ssl_.py", line 509, in _ssl_wrap_socket_impl
    return ssl_context.wrap_socket(sock, server_hostname=server_hostname)
  File "/usr/local/lib/python3.8/ssl.py", line 500, in wrap_socket
    return self.sslsocket_class._create(
  File "/usr/local/lib/python3.8/ssl.py", line 1073, in _create
    self.do_handshake()
  File "/usr/local/lib/python3.8/ssl.py", line 1342, in do_handshake
    self._sslobj.do_handshake()
ssl.SSLZeroReturnError: TLS/SSL connection has been closed (EOF) (_ssl.c:1135)

During handling of the above exception, another exception occurred:

Traceback (most recent call last):
  File "/home/airflow/.local/lib/python3.8/site-packages/urllib3/connectionpool.py", line 793, in urlopen
    response = self._make_request(
  File "/home/airflow/.local/lib/python3.8/site-packages/urllib3/connectionpool.py", line 491, in _make_request
    raise new_e
urllib3.exceptions.SSLError: TLS/SSL connection has been closed (EOF) (_ssl.c:1135)

The above exception was the direct cause of the following exception:

Traceback (most recent call last):
  File "/home/airflow/.local/lib/python3.8/site-packages/requests/adapters.py", line 486, in send
    resp = conn.urlopen(
  File "/home/airflow/.local/lib/python3.8/site-packages/urllib3/connectionpool.py", line 847, in urlopen
    retries = retries.increment(
  File "/home/airflow/.local/lib/python3.8/site-packages/urllib3/util/retry.py", line 515, in increment
    raise MaxRetryError(_pool, url, reason) from reason  # type: ignore[arg-type]
urllib3.exceptions.MaxRetryError: HTTPSConnectionPool(host='xecdapi.xe.com', port=443): Max retries exceeded with url: /v1/convert_from.json/?from=USD&to=NGN,GHS,KES,UGX,MAD,XOF,EGP (Caused by SSLError(SSLZeroReturnError(6, 'TLS/SSL connection has been closed (EOF) (_ssl.c:1135)')))

During handling of the above exception, another exception occurred:

Traceback (most recent call last):
  File "/home/airflow/.local/lib/python3.8/site-packages/airflow/models/taskinstance.py", line 444, in _execute_task
    result = _execute_callable(context=context, **execute_callable_kwargs)
  File "/home/airflow/.local/lib/python3.8/site-packages/airflow/models/taskinstance.py", line 414, in _execute_callable
    return execute_callable(context=context, **execute_callable_kwargs)
  File "/home/airflow/.local/lib/python3.8/site-packages/airflow/operators/python.py", line 200, in execute
    return_value = self.execute_callable()
  File "/home/airflow/.local/lib/python3.8/site-packages/airflow/operators/python.py", line 217, in execute_callable
    return self.python_callable(*self.op_args, **self.op_kwargs)
  File "/opt/airflow/dags/include/extract.py", line 22, in extract_data
    response = requests.get(url, auth=(api_id, api_key)).json()
  File "/home/airflow/.local/lib/python3.8/site-packages/requests/api.py", line 73, in get
    return request("get", url, params=params, **kwargs)
  File "/home/airflow/.local/lib/python3.8/site-packages/requests/api.py", line 59, in request
    return session.request(method=method, url=url, **kwargs)
  File "/home/airflow/.local/lib/python3.8/site-packages/requests/sessions.py", line 589, in request
    resp = self.send(prep, **send_kwargs)
  File "/home/airflow/.local/lib/python3.8/site-packages/requests/sessions.py", line 703, in send
    r = adapter.send(request, **kwargs)
  File "/home/airflow/.local/lib/python3.8/site-packages/requests/adapters.py", line 517, in send
    raise SSLError(e, request=request)
requests.exceptions.SSLError: HTTPSConnectionPool(host='xecdapi.xe.com', port=443): Max retries exceeded with url: /v1/convert_from.json/?from=USD&to=NGN,GHS,KES,UGX,MAD,XOF,EGP (Caused by SSLError(SSLZeroReturnError(6, 'TLS/SSL connection has been closed (EOF) (_ssl.c:1135)')))
[2024-04-12T12:48:51.633+0000] {taskinstance.py:1149} INFO - Marking task as FAILED. dag_id=KingFX_ETL, task_id=Extract_Response, execution_date=20240412T124828, start_date=20240412T124829, end_date=20240412T124851
[2024-04-12T12:48:51.646+0000] {standard_task_runner.py:107} ERROR - Failed to execute job 20 for task Extract_Response (HTTPSConnectionPool(host='xecdapi.xe.com', port=443): Max retries exceeded with url: /v1/convert_from.json/?from=USD&to=NGN,GHS,KES,UGX,MAD,XOF,EGP (Caused by SSLError(SSLZeroReturnError(6, 'TLS/SSL connection has been closed (EOF) (_ssl.c:1135)'))); 8364)
[2024-04-12T12:48:51.690+0000] {local_task_job_runner.py:234} INFO - Task exited with return code 1
