[2024-04-12T14:40:11.385+0000] {taskinstance.py:1979} INFO - Dependencies all met for dep_context=non-requeueable deps ti=<TaskInstance: KingFX_ETL.Transform_Response scheduled__2024-04-11T00:00:00+00:00 [queued]>
[2024-04-12T14:40:11.394+0000] {taskinstance.py:1979} INFO - Dependencies all met for dep_context=requeueable deps ti=<TaskInstance: KingFX_ETL.Transform_Response scheduled__2024-04-11T00:00:00+00:00 [queued]>
[2024-04-12T14:40:11.394+0000] {taskinstance.py:2193} INFO - Starting attempt 1 of 1
[2024-04-12T14:40:11.412+0000] {taskinstance.py:2217} INFO - Executing <Task(PythonOperator): Transform_Response> on 2024-04-11 00:00:00+00:00
[2024-04-12T14:40:11.419+0000] {standard_task_runner.py:60} INFO - Started process 10055 to run task
[2024-04-12T14:40:11.422+0000] {standard_task_runner.py:87} INFO - Running: ['***', 'tasks', 'run', 'KingFX_ETL', 'Transform_Response', 'scheduled__2024-04-11T00:00:00+00:00', '--job-id', '26', '--raw', '--subdir', 'DAGS_FOLDER/include/fx_dag.py', '--cfg-path', '/tmp/tmp4u322krh']
[2024-04-12T14:40:11.425+0000] {standard_task_runner.py:88} INFO - Job 26: Subtask Transform_Response
[2024-04-12T14:40:11.481+0000] {task_command.py:423} INFO - Running <TaskInstance: KingFX_ETL.Transform_Response scheduled__2024-04-11T00:00:00+00:00 [running]> on host ab7b3f965e72
[2024-04-12T14:40:11.567+0000] {taskinstance.py:2513} INFO - Exporting env vars: AIRFLOW_CTX_DAG_OWNER='***' AIRFLOW_CTX_DAG_ID='KingFX_ETL' AIRFLOW_CTX_TASK_ID='Transform_Response' AIRFLOW_CTX_EXECUTION_DATE='2024-04-11T00:00:00+00:00' AIRFLOW_CTX_TRY_NUMBER='1' AIRFLOW_CTX_DAG_RUN_ID='scheduled__2024-04-11T00:00:00+00:00'
[2024-04-12T14:40:11.569+0000] {taskinstance.py:2731} ERROR - Task failed with exception
Traceback (most recent call last):
  File "/home/airflow/.local/lib/python3.8/site-packages/airflow/models/taskinstance.py", line 444, in _execute_task
    result = _execute_callable(context=context, **execute_callable_kwargs)
  File "/home/airflow/.local/lib/python3.8/site-packages/airflow/models/taskinstance.py", line 414, in _execute_callable
    return execute_callable(context=context, **execute_callable_kwargs)
  File "/home/airflow/.local/lib/python3.8/site-packages/airflow/operators/python.py", line 200, in execute
    return_value = self.execute_callable()
  File "/home/airflow/.local/lib/python3.8/site-packages/airflow/operators/python.py", line 217, in execute_callable
    return self.python_callable(*self.op_args, **self.op_kwargs)
TypeError: transform_data() missing 1 required positional argument: 'data'
[2024-04-12T14:40:11.582+0000] {taskinstance.py:1149} INFO - Marking task as FAILED. dag_id=KingFX_ETL, task_id=Transform_Response, execution_date=20240411T000000, start_date=20240412T144011, end_date=20240412T144011
[2024-04-12T14:40:11.596+0000] {standard_task_runner.py:107} ERROR - Failed to execute job 26 for task Transform_Response (transform_data() missing 1 required positional argument: 'data'; 10055)
[2024-04-12T14:40:11.635+0000] {local_task_job_runner.py:234} INFO - Task exited with return code 1
[2024-04-12T19:46:27.624+0000] {taskinstance.py:1979} INFO - Dependencies all met for dep_context=non-requeueable deps ti=<TaskInstance: KingFX_ETL.Transform_Response scheduled__2024-04-11T00:00:00+00:00 [queued]>
[2024-04-12T19:46:27.634+0000] {taskinstance.py:1979} INFO - Dependencies all met for dep_context=requeueable deps ti=<TaskInstance: KingFX_ETL.Transform_Response scheduled__2024-04-11T00:00:00+00:00 [queued]>
[2024-04-12T19:46:27.635+0000] {taskinstance.py:2193} INFO - Starting attempt 1 of 1
[2024-04-12T19:46:27.651+0000] {taskinstance.py:2217} INFO - Executing <Task(PythonOperator): Transform_Response> on 2024-04-11 00:00:00+00:00
[2024-04-12T19:46:27.656+0000] {standard_task_runner.py:60} INFO - Started process 169 to run task
[2024-04-12T19:46:27.658+0000] {standard_task_runner.py:87} INFO - Running: ['***', 'tasks', 'run', 'KingFX_ETL', 'Transform_Response', 'scheduled__2024-04-11T00:00:00+00:00', '--job-id', '37', '--raw', '--subdir', 'DAGS_FOLDER/include/fx_dag.py', '--cfg-path', '/tmp/tmpnjzw7ck8']
[2024-04-12T19:46:27.662+0000] {standard_task_runner.py:88} INFO - Job 37: Subtask Transform_Response
[2024-04-12T19:46:27.716+0000] {task_command.py:423} INFO - Running <TaskInstance: KingFX_ETL.Transform_Response scheduled__2024-04-11T00:00:00+00:00 [running]> on host 65f2ce3f86e2
[2024-04-12T19:46:27.792+0000] {taskinstance.py:2513} INFO - Exporting env vars: AIRFLOW_CTX_DAG_OWNER='***' AIRFLOW_CTX_DAG_ID='KingFX_ETL' AIRFLOW_CTX_TASK_ID='Transform_Response' AIRFLOW_CTX_EXECUTION_DATE='2024-04-11T00:00:00+00:00' AIRFLOW_CTX_TRY_NUMBER='1' AIRFLOW_CTX_DAG_RUN_ID='scheduled__2024-04-11T00:00:00+00:00'
[2024-04-12T19:46:27.795+0000] {taskinstance.py:2731} ERROR - Task failed with exception
Traceback (most recent call last):
  File "/home/airflow/.local/lib/python3.8/site-packages/airflow/models/taskinstance.py", line 444, in _execute_task
    result = _execute_callable(context=context, **execute_callable_kwargs)
  File "/home/airflow/.local/lib/python3.8/site-packages/airflow/models/taskinstance.py", line 414, in _execute_callable
    return execute_callable(context=context, **execute_callable_kwargs)
  File "/home/airflow/.local/lib/python3.8/site-packages/airflow/operators/python.py", line 200, in execute
    return_value = self.execute_callable()
  File "/home/airflow/.local/lib/python3.8/site-packages/airflow/operators/python.py", line 217, in execute_callable
    return self.python_callable(*self.op_args, **self.op_kwargs)
  File "/opt/airflow/dags/include/transform.py", line 13, in transform_data
    timestamp = response['timestamp']
KeyError: 'timestamp'
[2024-04-12T19:46:27.806+0000] {taskinstance.py:1149} INFO - Marking task as FAILED. dag_id=KingFX_ETL, task_id=Transform_Response, execution_date=20240411T000000, start_date=20240412T194627, end_date=20240412T194627
[2024-04-12T19:46:27.817+0000] {standard_task_runner.py:107} ERROR - Failed to execute job 37 for task Transform_Response ('timestamp'; 169)
[2024-04-12T19:46:27.832+0000] {local_task_job_runner.py:234} INFO - Task exited with return code 1
[2024-04-12T20:23:13.956+0000] {taskinstance.py:1979} INFO - Dependencies all met for dep_context=non-requeueable deps ti=<TaskInstance: KingFX_ETL.Transform_response scheduled__2024-04-11T00:00:00+00:00 [queued]>
[2024-04-12T20:23:13.965+0000] {taskinstance.py:1979} INFO - Dependencies all met for dep_context=requeueable deps ti=<TaskInstance: KingFX_ETL.Transform_response scheduled__2024-04-11T00:00:00+00:00 [queued]>
[2024-04-12T20:23:13.966+0000] {taskinstance.py:2193} INFO - Starting attempt 1 of 1
[2024-04-12T20:23:13.980+0000] {taskinstance.py:2217} INFO - Executing <Task(PythonOperator): Transform_response> on 2024-04-11 00:00:00+00:00
[2024-04-12T20:23:13.984+0000] {standard_task_runner.py:60} INFO - Started process 746 to run task
[2024-04-12T20:23:13.987+0000] {standard_task_runner.py:87} INFO - Running: ['***', 'tasks', 'run', 'KingFX_ETL', 'Transform_response', 'scheduled__2024-04-11T00:00:00+00:00', '--job-id', '45', '--raw', '--subdir', 'DAGS_FOLDER/include/fx_dag.py', '--cfg-path', '/tmp/tmpubi8cviv']
[2024-04-12T20:23:13.990+0000] {standard_task_runner.py:88} INFO - Job 45: Subtask Transform_response
[2024-04-12T20:23:14.039+0000] {task_command.py:423} INFO - Running <TaskInstance: KingFX_ETL.Transform_response scheduled__2024-04-11T00:00:00+00:00 [running]> on host 65f2ce3f86e2
[2024-04-12T20:23:14.112+0000] {taskinstance.py:2513} INFO - Exporting env vars: AIRFLOW_CTX_DAG_OWNER='***' AIRFLOW_CTX_DAG_ID='KingFX_ETL' AIRFLOW_CTX_TASK_ID='Transform_response' AIRFLOW_CTX_EXECUTION_DATE='2024-04-11T00:00:00+00:00' AIRFLOW_CTX_TRY_NUMBER='1' AIRFLOW_CTX_DAG_RUN_ID='scheduled__2024-04-11T00:00:00+00:00'
[2024-04-12T20:23:14.115+0000] {taskinstance.py:2731} ERROR - Task failed with exception
Traceback (most recent call last):
  File "/home/airflow/.local/lib/python3.8/site-packages/airflow/models/taskinstance.py", line 444, in _execute_task
    result = _execute_callable(context=context, **execute_callable_kwargs)
  File "/home/airflow/.local/lib/python3.8/site-packages/airflow/models/taskinstance.py", line 414, in _execute_callable
    return execute_callable(context=context, **execute_callable_kwargs)
  File "/home/airflow/.local/lib/python3.8/site-packages/airflow/operators/python.py", line 200, in execute
    return_value = self.execute_callable()
  File "/home/airflow/.local/lib/python3.8/site-packages/airflow/operators/python.py", line 217, in execute_callable
    return self.python_callable(*self.op_args, **self.op_kwargs)
  File "/opt/airflow/dags/include/transform.py", line 13, in transform_data
    timestamp = response['timestamp']
KeyError: 'timestamp'
[2024-04-12T20:23:14.128+0000] {taskinstance.py:1149} INFO - Marking task as FAILED. dag_id=KingFX_ETL, task_id=Transform_response, execution_date=20240411T000000, start_date=20240412T202313, end_date=20240412T202314
[2024-04-12T20:23:14.139+0000] {standard_task_runner.py:107} ERROR - Failed to execute job 45 for task Transform_response ('timestamp'; 746)
[2024-04-12T20:23:14.160+0000] {local_task_job_runner.py:234} INFO - Task exited with return code 1
[2024-04-12T21:36:16.750+0000] {taskinstance.py:1979} INFO - Dependencies all met for dep_context=non-requeueable deps ti=<TaskInstance: KingFX_ETL.Transform_response scheduled__2024-04-11T00:00:00+00:00 [queued]>
[2024-04-12T21:36:16.759+0000] {taskinstance.py:1979} INFO - Dependencies all met for dep_context=requeueable deps ti=<TaskInstance: KingFX_ETL.Transform_response scheduled__2024-04-11T00:00:00+00:00 [queued]>
[2024-04-12T21:36:16.760+0000] {taskinstance.py:2193} INFO - Starting attempt 1 of 1
[2024-04-12T21:36:16.775+0000] {taskinstance.py:2217} INFO - Executing <Task(PythonOperator): Transform_response> on 2024-04-11 00:00:00+00:00
[2024-04-12T21:36:16.780+0000] {standard_task_runner.py:60} INFO - Started process 1847 to run task
[2024-04-12T21:36:16.782+0000] {standard_task_runner.py:87} INFO - Running: ['***', 'tasks', 'run', 'KingFX_ETL', 'Transform_response', 'scheduled__2024-04-11T00:00:00+00:00', '--job-id', '49', '--raw', '--subdir', 'DAGS_FOLDER/include/fx_dag.py', '--cfg-path', '/tmp/tmpcs5olo4a']
[2024-04-12T21:36:16.785+0000] {standard_task_runner.py:88} INFO - Job 49: Subtask Transform_response
[2024-04-12T21:36:16.832+0000] {task_command.py:423} INFO - Running <TaskInstance: KingFX_ETL.Transform_response scheduled__2024-04-11T00:00:00+00:00 [running]> on host 65f2ce3f86e2
[2024-04-12T21:36:16.900+0000] {taskinstance.py:2513} INFO - Exporting env vars: AIRFLOW_CTX_DAG_OWNER='***' AIRFLOW_CTX_DAG_ID='KingFX_ETL' AIRFLOW_CTX_TASK_ID='Transform_response' AIRFLOW_CTX_EXECUTION_DATE='2024-04-11T00:00:00+00:00' AIRFLOW_CTX_TRY_NUMBER='1' AIRFLOW_CTX_DAG_RUN_ID='scheduled__2024-04-11T00:00:00+00:00'
[2024-04-12T21:36:16.902+0000] {taskinstance.py:2731} ERROR - Task failed with exception
Traceback (most recent call last):
  File "/home/airflow/.local/lib/python3.8/site-packages/airflow/models/taskinstance.py", line 444, in _execute_task
    result = _execute_callable(context=context, **execute_callable_kwargs)
  File "/home/airflow/.local/lib/python3.8/site-packages/airflow/models/taskinstance.py", line 414, in _execute_callable
    return execute_callable(context=context, **execute_callable_kwargs)
  File "/home/airflow/.local/lib/python3.8/site-packages/airflow/operators/python.py", line 200, in execute
    return_value = self.execute_callable()
  File "/home/airflow/.local/lib/python3.8/site-packages/airflow/operators/python.py", line 217, in execute_callable
    return self.python_callable(*self.op_args, **self.op_kwargs)
  File "/opt/airflow/dags/include/transform.py", line 13, in transform_data
    timestamp = response['timestamp']
KeyError: 'timestamp'
[2024-04-12T21:36:16.913+0000] {taskinstance.py:1149} INFO - Marking task as FAILED. dag_id=KingFX_ETL, task_id=Transform_response, execution_date=20240411T000000, start_date=20240412T213616, end_date=20240412T213616
[2024-04-12T21:36:16.923+0000] {standard_task_runner.py:107} ERROR - Failed to execute job 49 for task Transform_response ('timestamp'; 1847)
[2024-04-12T21:36:16.955+0000] {local_task_job_runner.py:234} INFO - Task exited with return code 1
[2024-04-12T22:02:07.111+0000] {taskinstance.py:1979} INFO - Dependencies all met for dep_context=non-requeueable deps ti=<TaskInstance: KingFX_ETL.Transform_response scheduled__2024-04-11T00:00:00+00:00 [queued]>
[2024-04-12T22:02:07.121+0000] {taskinstance.py:1979} INFO - Dependencies all met for dep_context=requeueable deps ti=<TaskInstance: KingFX_ETL.Transform_response scheduled__2024-04-11T00:00:00+00:00 [queued]>
[2024-04-12T22:02:07.121+0000] {taskinstance.py:2193} INFO - Starting attempt 1 of 1
[2024-04-12T22:02:07.136+0000] {taskinstance.py:2217} INFO - Executing <Task(PythonOperator): Transform_response> on 2024-04-11 00:00:00+00:00
[2024-04-12T22:02:07.141+0000] {standard_task_runner.py:60} INFO - Started process 2268 to run task
[2024-04-12T22:02:07.144+0000] {standard_task_runner.py:87} INFO - Running: ['***', 'tasks', 'run', 'KingFX_ETL', 'Transform_response', 'scheduled__2024-04-11T00:00:00+00:00', '--job-id', '61', '--raw', '--subdir', 'DAGS_FOLDER/include/fx_dag.py', '--cfg-path', '/tmp/tmpbg28j9_p']
[2024-04-12T22:02:07.146+0000] {standard_task_runner.py:88} INFO - Job 61: Subtask Transform_response
[2024-04-12T22:02:07.193+0000] {task_command.py:423} INFO - Running <TaskInstance: KingFX_ETL.Transform_response scheduled__2024-04-11T00:00:00+00:00 [running]> on host 65f2ce3f86e2
[2024-04-12T22:02:07.263+0000] {taskinstance.py:2513} INFO - Exporting env vars: AIRFLOW_CTX_DAG_OWNER='***' AIRFLOW_CTX_DAG_ID='KingFX_ETL' AIRFLOW_CTX_TASK_ID='Transform_response' AIRFLOW_CTX_EXECUTION_DATE='2024-04-11T00:00:00+00:00' AIRFLOW_CTX_TRY_NUMBER='1' AIRFLOW_CTX_DAG_RUN_ID='scheduled__2024-04-11T00:00:00+00:00'
[2024-04-12T22:02:07.265+0000] {taskinstance.py:2731} ERROR - Task failed with exception
Traceback (most recent call last):
  File "/home/airflow/.local/lib/python3.8/site-packages/airflow/models/taskinstance.py", line 444, in _execute_task
    result = _execute_callable(context=context, **execute_callable_kwargs)
  File "/home/airflow/.local/lib/python3.8/site-packages/airflow/models/taskinstance.py", line 414, in _execute_callable
    return execute_callable(context=context, **execute_callable_kwargs)
  File "/home/airflow/.local/lib/python3.8/site-packages/airflow/operators/python.py", line 200, in execute
    return_value = self.execute_callable()
  File "/home/airflow/.local/lib/python3.8/site-packages/airflow/operators/python.py", line 217, in execute_callable
    return self.python_callable(*self.op_args, **self.op_kwargs)
  File "/opt/airflow/dags/include/transform.py", line 13, in transform_data
    timestamp = response['timestamp']
KeyError: 'timestamp'
[2024-04-12T22:02:07.276+0000] {taskinstance.py:1149} INFO - Marking task as FAILED. dag_id=KingFX_ETL, task_id=Transform_response, execution_date=20240411T000000, start_date=20240412T220207, end_date=20240412T220207
[2024-04-12T22:02:07.287+0000] {standard_task_runner.py:107} ERROR - Failed to execute job 61 for task Transform_response ('timestamp'; 2268)
[2024-04-12T22:02:07.316+0000] {local_task_job_runner.py:234} INFO - Task exited with return code 1
[2024-04-12T22:36:26.633+0000] {taskinstance.py:1979} INFO - Dependencies all met for dep_context=non-requeueable deps ti=<TaskInstance: KingFX_ETL.Transform_response scheduled__2024-04-11T00:00:00+00:00 [queued]>
[2024-04-12T22:36:26.645+0000] {taskinstance.py:1979} INFO - Dependencies all met for dep_context=requeueable deps ti=<TaskInstance: KingFX_ETL.Transform_response scheduled__2024-04-11T00:00:00+00:00 [queued]>
[2024-04-12T22:36:26.646+0000] {taskinstance.py:2193} INFO - Starting attempt 1 of 1
[2024-04-12T22:36:26.663+0000] {taskinstance.py:2217} INFO - Executing <Task(PythonOperator): Transform_response> on 2024-04-11 00:00:00+00:00
[2024-04-12T22:36:26.668+0000] {standard_task_runner.py:60} INFO - Started process 2815 to run task
[2024-04-12T22:36:26.673+0000] {standard_task_runner.py:87} INFO - Running: ['***', 'tasks', 'run', 'KingFX_ETL', 'Transform_response', 'scheduled__2024-04-11T00:00:00+00:00', '--job-id', '69', '--raw', '--subdir', 'DAGS_FOLDER/include/fx_dag.py', '--cfg-path', '/tmp/tmp7akssho0']
[2024-04-12T22:36:26.676+0000] {standard_task_runner.py:88} INFO - Job 69: Subtask Transform_response
[2024-04-12T22:36:26.730+0000] {task_command.py:423} INFO - Running <TaskInstance: KingFX_ETL.Transform_response scheduled__2024-04-11T00:00:00+00:00 [running]> on host 65f2ce3f86e2
[2024-04-12T22:36:26.811+0000] {taskinstance.py:2513} INFO - Exporting env vars: AIRFLOW_CTX_DAG_OWNER='***' AIRFLOW_CTX_DAG_ID='KingFX_ETL' AIRFLOW_CTX_TASK_ID='Transform_response' AIRFLOW_CTX_EXECUTION_DATE='2024-04-11T00:00:00+00:00' AIRFLOW_CTX_TRY_NUMBER='1' AIRFLOW_CTX_DAG_RUN_ID='scheduled__2024-04-11T00:00:00+00:00'
[2024-04-12T22:36:26.813+0000] {taskinstance.py:2731} ERROR - Task failed with exception
Traceback (most recent call last):
  File "/home/airflow/.local/lib/python3.8/site-packages/airflow/models/taskinstance.py", line 444, in _execute_task
    result = _execute_callable(context=context, **execute_callable_kwargs)
  File "/home/airflow/.local/lib/python3.8/site-packages/airflow/models/taskinstance.py", line 414, in _execute_callable
    return execute_callable(context=context, **execute_callable_kwargs)
  File "/home/airflow/.local/lib/python3.8/site-packages/airflow/operators/python.py", line 200, in execute
    return_value = self.execute_callable()
  File "/home/airflow/.local/lib/python3.8/site-packages/airflow/operators/python.py", line 217, in execute_callable
    return self.python_callable(*self.op_args, **self.op_kwargs)
  File "/opt/airflow/dags/include/transform.py", line 13, in transform_data
    timestamp = response['timestamp']
KeyError: 'timestamp'
[2024-04-12T22:36:26.826+0000] {taskinstance.py:1149} INFO - Marking task as FAILED. dag_id=KingFX_ETL, task_id=Transform_response, execution_date=20240411T000000, start_date=20240412T223626, end_date=20240412T223626
[2024-04-12T22:36:26.837+0000] {standard_task_runner.py:107} ERROR - Failed to execute job 69 for task Transform_response ('timestamp'; 2815)
[2024-04-12T22:36:26.845+0000] {local_task_job_runner.py:234} INFO - Task exited with return code 1
